Workbook

Sheet 개정내역
A1: 공동주택 견적지침서 개정내역 리스트 (2023. 04. 17)
A3: 구 분 | C3: 내 용 | E3: 변 경 사 유 | F3: 개정일자 | L3: 비 고 | N3: 개정일 | O3: 제정일
C4: 변 경 전 | D4: 변 경 후 | F4: 20년 | G4: 21년 | H4: 22년 | I4: 23년 | J4: 24년 | K4: 25년 | N4: 44748 | O4: 42697
A5: 원재료(공통) | B5: 공통사항 | C5: ▶구매대행수수료 항목 추가 | E5: 구매대행 법인설립에 따른 항목추가 | F5: 44097 | M5: 동대구신천 실행결재일(최초반영현장)
C6: 미적용 | D6: 자제공사 2% / 도급공사 1% 적용
A7: 원재료-03 | B7: 벽돌류 | C7: ▶욕조설치용 벽돌매수 변경 | E7: 실시공물량으로 기준변경 | H7: 44748
C8: 세대당 10매 산출(자재할증없음, 쌓기물량 제외) | D8: 세대당 30매 산출(자재할증없음, 쌓기물량 제외)
C9: ▶분합문 및 욕실문, 발코니도어 하부 조적 산출기준 추가 | E9: 산출기준 불명확으로 인한 기준정립 | G9: 44469
C10: 기준 불명확 | D10: 분합문 및 욕실문, 발코니도어 하부 조적 산출 (매로 산출, 쌓기물량 제외)
A11: 원재료-07 | B11: 타일(자재) | C11: ▶세대 벽/바닥타일 할증률 변경 | E11: 22.03.11 정도경영팀 "타일자재 관리방안" 공지사항 | H11: 44631 | N11: 20.12.14 정도경영팀 "타일자재 관리방안" 공지사항 | Q11: 세대할증 2%
C12: 세대 벽/바닥타일 할증률 2% | D12: 세대 벽/바닥타일 할증률 0% | N12: 22.03.11 정도경영팀 "타일자재 관리방안" 공지사항 | Q12: 세대할증 0%
A13: 건축-01 | B13: 철근콘크리트공사 | C13: ▶와이어메쉬 산출기준 변경 | E13: 발주공종 반영에 따른 공종분개 | H13: 44748
C14: 외주항목으로 자재포함 산출 | D14: 자재(원재료비)와 시공(외주)분리 산출
C15: ▶무근콘크리트 견적기준 변경(주차장 중층구간 APT PIT) | E15: 실시공물량으로 기준변경 | H15: 44748
C16: 도면표기대로 산출(무근두께 미표기시 100T적용) | D16: 도면표기 여부 관계없이 미산출
C17: ▶전이층 슬라브 가설시설 견적기준 추가 | E17: 산출기준 불명확으로 인한 기준정립 | H17: 44748
C18: 별도 기준없음 | D18: 전이층 높이 관계없이 조립식동바리 일괄적용(전이층하부) (안전검토서 제출시 해당 내용으로 별도산출 검토 - 당팀 협의)
C19: ▶갱폼 견적기준 변경 | H19: 44748
C20: 기준층+최상층 외벽, 피난층 외벽 | D20: 기준층+최상층 외벽, 피난층 외벽 + 옥상 낮은 난간
C21: ▶지수판 견적기준 변경 | E21: 실시공물량으로 기준변경 | H21: 44748
C22: 거푸집단가 포함항목으로 미산출 | D22: 기초끊어치기구간 및 지하층둘레 X (층수+1) 별도 산출
C23: ▶EPS블럭 산출기준 변경 | E23: 발주공종 반영에 따른 공종분개 | H23: 44748
C24: 외주항목으로 자재포함 산출 | D24: 자재(원재료비)와 시공(외주)분리 산출
C25: ▶결로방지단열재(최상층 세대옹벽 상부) 견적기준 변경 및 추가 | E25: 실시공물량으로 기준변경 | H25: 44748
C26: 도면표기대로 산출 | D26: 도면표기 여부 관계없이 산출 (세대 옹벽길이 X H(450MM))
C27: ▶골조방수턱 산출기준 변경 | E27: 실시공물량으로 기준변경 | H27: 44748
C28: 마감 조적 산출시 레미콘타설(무근) 산출 | D28: 골조 각 공종별 산출(레미콘/거푸집/철근)
C29: ▶주차장 램프연석 산출기준 변경 | E29: 실시공물량으로 기준변경 | H29: 44748
C30: 미장공사 M단위 산출 | D30: 골조 각 공종별 산출(레미콘/거푸집)
C31: ▶합벽 띠장철근 산출기준 추가 | E31: 산출기준 불명확으로 인한 기준정립 | H31: 44748
C32: 별도 기준없음 | D32: 합벽띠장부 철근이음 추가 산출(토목도면 참고)
C33: ▶인방보 보조근 산출기준 추가 | E33: 산출기준 불명확으로 인한 기준정립 | H33: 44748
C34: 별도 기준없음 | D34: 보춤1000mm이상 (H10@300) -> 미표기일때도 산출
C35: ▶AL폼 저소음시스템 산출기준 추가 | E35: 산출기준 불명확으로 인한 기준정립 | H35: 44748
C36: 별도 기준없음 | D36: 도심지공사일 경우 산출
A37: 건축-03 | B37: 방수공사 | C37: ▶발코니 액체방수 올림 견적기준 추가 | E37: 산출기준 불명확으로 인한 기준정립 | H37: 44748
C38: 기준 불명확 | D38: 바닥마감선(타일마감) 높이까지 적용
C39: ▶주차장내벽(PIT/동주위 벽체 등) 바닥 액체방수 한계 미적용 | E39: 물량산출 범위 과다로 인한 기준변경 | H39: 44748
C40: 바닥 방수한계 H=200 산출 | D40: 기준삭제 (바닥 끊어치기 구간만 액체방수 적용, 내벽 방수 필요성 부재로 삭제)
C41: ▶지하주차장 외벽방수 높이 기준 추가 | E41: 산출기준 불명확으로 인한 기준정립 | H41: 44748
...

Sheet 표지
A8: 공 동 주 택 공 사
A9: 견 적 · 실 행 예 산 작 성 지 침 서
A32: 2022. 07
A39: 건축실행내역팀

Sheet 목차
A1: 목 차
A5: 제 1부 | C5: 일반사항
B7: 제 1장 | D7: 견적일반 | H7: ------------------- | J7: 4 ~ 6
B9: 제 2장 | D9: 실행예산 작성규칙 | H9: ------------------- | J9: 7 ~ 8
B11: 제 3장 | D11: 실행예산 편성 흐름도 | H11: ------------------- | J11: 9
A13: 제 2부 | C13: 공종별 견적기준
B15: 제 1장 | D15: 원재료비 | H15: ------------------- | J15: 12 ~ 14
B17: 제 2장 | D17: 건축공사(외주) | H17: ------------------- | J17: 16 ~ 68
B19: 제 3장 | D19: 자재납품(건축) | H19: ------------------- | J19: 70 ~ 86
A21: 제 3부 | C21: 기타 견적기준
B23: 제 1장 | D23: 주요부위 산출기준 | H23: ------------------- | J23: 88 ~ 89
B25: 제 2장 | D25: 부자재 환산수량 | H25: ------------------- | J25: 90
B27: 제 3장 | D27: 재료할증기준 | H27: ------------------- | J27: 91
L34: 품 명 | M34: 규 격 | N34: 단 위 | O34: 비 고
L35: 01. 파일 | N35: 식 | O35: 토목실행내역팀 작성분
L36: 02. 레미콘 | N36: 식
L37: 03. 철근 | N37: 식
L38: 04. 벽돌 | N38: 식
L39: 05. 시멘트 | N39: 식
L40: 06. 레미탈 | N40: 식
L41: 07. 골재 | N41: 식
L42: 08. 타일 | N42: 식
L43: 09. 단열재 | N43: 식 | O43: 골조, 조적, 내장, 층간소음재 등으로 공종별산출
L45: 품 명 | M45: 규 격 | N45: 단 위 | O45: 비 고
L46: 01. 기초 및 지정공사 | N46: 식 | O46: 토목실행내역팀 작성분
L47: 02. 영구배수공사 | N47: 식
L48: 03. 철근콘크리트공사 | N48: 식 | O48: 하위공종으로 가설, 거푸집, 철근, 콘크리트 구성
L49: 04. 데크공사 | N49: 식
L50: 05. 방수공사 | N50: 식
L51: 06. 견출공사 | N51: 식
L52: 07. 조적공사 | N52: 식
L53: 08. 미장공사 | N53: 식
L54: 09. 타일공사 | N54: 식
L55: 10. 석공사 | N55: 식
L56: 11. 테라죠공사 | N56: 식
L57: 12. 금속 및 금속창호공사 | N57: 식
L58: 13. AL창호공사 | N58: 식
L59: 14. PL창호공사 | N59: 식 | O59: 하위공종으로 기본형, 확장형으로 구성
L60: 15. 유리공사 | N60: 식 | O60: 하위공종으로 기본형, 확장형으로 구성
L61: 16. 내장목공사 | N61: 식
...

Sheet 일반사항
A8: - 제 1 부 -
A16: 일반사항

Sheet 1.견적일반
C2: 구분 | D2: 일반사항 | E2: 공종명 | G2: 1. 견적일반 | H2: 개정 번호 | I2: REV.03 | J2: 제정일 | K2: =+개정내역!$O$4 -> 42697
J3: 개정일 | K3: =+개정내역!$N$4 -> 44748
B5: ▶견적일반
B6: 1. 작성목적
B7: 본 지침서는 SM그룹 건설부문 예산작성시 공동주택공사 원가계산을 위한 기초자료이다.
B8: 각 공종별 수량을 바탕으로 적정한 공사원가를 산출하기 위한 기준을 정하여 적산 및 견적업무의 통일성과 효율화를 통해
B9: 합리적인 원가관리를 함으로써 이윤의 극대화를 도모하는데 그 목적이 있다.
B11: 적산 : 공사에 소요되는 재료의 물량을 산출하는 과정
B12: 견적 : 공사물량에 해당품목에 적절한 단가를 적용하여 공사비를 산정하는 과정
B13: 견적이란 주어진 설계도서를 바탕으로 건물의 공사비를 산정하는 것을 의미한다.
B16: 2. 견적의 종류
B17: 개산견적 : 설계도서가 미비하거나 정밀산출시간이 부족할 때 용도, 규모 및 성격이 유사한 공사자료를 이용하여 개략공사비를
B18: 추정하는 방법
B19: 상세견적 : 완비된 설계도서, 시방서에 의거하여 정밀한 적산, 견적을 하여 공사비를 산정하는 방법
B22: 3. 견적방법 및 순서
B23: 1) 설계도서 이해 | D23: : 건축/구조 도면을 상호 체크하여 건축물 파악
B24: 2) 공사조건 조사 | D24: : 현장위치, 대지지반 등 전반적인 공사여건 조사
B25: 3) 시공계획 | D25: : 가설공사, 공사기간, 투입인원, 장비동원 등을 계획
B26: 4) 시공물량산정 | D26: : 적산작업을 통한 물량산출
B27: 5) 단가조사 분석 및 결정 | D27: : 기존계약단가, 전문업체견적 등을 활용한 단가결정
B28: 6) 직접공사비 산정 | D28: : 적산물량에 단가를 반영
B29: 7) 간접공사비 산정 | D29: : 공사기간, 투입인원, 경비 등을 반영
B30: 8) 전체공사비 산정 | D30: : 직접공사비, 간접공사비, 이윤 등을 고려하여 산정
B41: 4. 내역구성
B42: 공종별 내역구성 및 순서는 다음과 같은 순으로 작성한다.
B43: [원재료비]
B54: [건축공사(외주)]
B77: [자재납품(건축)]
B92: ※ 이하 현장별 신규 항목이 발생되는 경우 신규품명이 발생될 수 있다.
B94: 5. 수량산출 동구분 기준
B109: ※ 내역 : 아파트, 부대시설로 구분 (부대시설은 아파트 PIT, 지하주차장, 부속동 및 근린생활시설 포함)
B110: ※ 수량산출 : 아파트 지상, 아파트 공용, 아파트 지하, 주차장 및 부속동, 근린생활시설로 구분산출
B111: (지하층 EV홀 물량 - 내역 : 아파트 / 수량산출 : 아파트 공용)

Sheet 2.작성규칙
C2: 구분 | D2: 일반사항 | E2: 공종명 | G2: 2. 실행예산 작성규칙 | H2: 개정 번호 | I2: REV.03 | J2: 제정일 | K2: =+개정내역!$O$4 -> 42697
J3: 개정일 | K3: =+개정내역!$N$4 -> 44748
B5: ▶실행예산 작성규칙
B6: 1. 작성목적
B7: 이 규칙은 국내 공동주택공사의 실행예산작성 기준을 설정하여 철저한 예산관리와 효율적인 공사집행이 가능하도록 작성기준
B8: 및 양식을 표준화하여, 합리적인 원가관리를 함으로써 이윤의 극대화를 도모하는데 그 목적이 있다.
B10: 2. 적용범위
B11: 이 규칙은 국내 공동주택공사 중 건축공사의 실행예산 작성에 적용된다.
B13: 3. 실행예산의 구분
B14: 실행예산은 본(本)예산, 변경(變更)예산, 가(假)예산, 부분(部分)예산으로 구분한다.
B16: 4. 용어의 정의
B17: 이 규칙에서 사용하는 용어의 정의는 다음과 같다.
B18: 1)“본(本)”예산이란 신규공사에 소요되는 공사비를 편성한 예산을 말한다.
B19: 2)“변경(變更)예산”이란 공사의 여건변경 등 타당하다고 인정되는 사유발생시 본 예산을 변경, 수정한 예산을 말한다.
... B73: (문서는 준공 완료 후 폐기처분하고 디스켓으로 보관)

Sheet 3. 편성흐름도
C2: 구분 | D2: 일반사항 | E2: 공종명 | G2: 3. 실행예산 편성 흐름도 | H2: 개정 번호 | I2: REV.03 | J2: 제정일 | K2: =+개정내역!$O$4 -> 42697
J3: 개정일 | K3: =+개정내역!$N$4 -> 44748
B5: ▶실행예산 편성흐름도

Sheet 공종별견적기준
A8: - 제 2 부 -
A16: 공종별 견적기준

Sheet 원재료비
A8: - 제 1 장 -
A16: 원재료비

Sheet 각공종별
C2: 구분 | D2: 원재료비 | E2: 공종명 | G2: 각 공종별 | H2: 개정 번호 | I2: REV.03 | J2: 제정일 | K2: =+개정내역!$O$4 -> 42697
J3: 개정일 | K3: =+개정내역!$N$4 -> 44748
B5: 품 명 | C5: 규 격 | F5: 단위 | G5: 주 요 내 용 | L5: 비 고
B6: 1. 레미콘
B7: 레미콘 | C7: 규격별 | F7: M3 | G7: 할증 : 철콘 1% / 무근(버림포함) 2% 적용
B8: 레미콘(타일바닥용) | C8: 몰탈1:3 | F8: M3 | G8: 할증없음
B9: 섬유보강재 | C9: 무근속/주차장지붕 | F9: M3 | G9: 할증없음
B10: 와이어메쉬(자재) | C10: #8-150*150 | F10: M2 | G10: 할증없음
B12: [견적지침]
B13: 레미콘 | C13: 25-18-08,버림 | F13: M3 | G13: 버림콘크리트 두께 60mm, 내민길이100mm 적용
B14: 레미콘 | C14: 25-18-12,무근 | F14: M3 | G14: 주차장 지붕, 아파트 및 부속동(전기,발전기실) 내부 바닥
G15: 아파트PIT(중층) 무근 도면표기시 미산출 | L15: 개정
G16: 무근두께 도면 미표기시 100T 적용
B17: 레미콘 | C17: 25-21-12,무근 | F17: M3 | G17: 지하주차장 내부 바닥, 아파트 및 부속동 지붕
B18: 레미콘 | C18: C급콘크리트(25-18-12) | F18: M3 | G18: 기초꺾임옹벽으로 단면도에 C급 표현있을 경우 산출
B19: 섬유보강재 | C19: 무근속/주차장ROOF | F19: M3 | G19: 주차장 지붕상부(흙 묻히는부분) / 피로티 바닥
B20: 와이어메쉬(자재) | C20: #8-150*150 | F20: M2 | G20: 주차장 내부 / 아파트 지붕 바닥
G21: 자재, 시공 항목 분리 | L21: 개정
B23: 2. 철근
B24: 이형철근(SD400) | C24: 규격별 | F24: TON | G24: 할증 : 철근 3% 적용
B25: 이형철근(SD500) | C25: 규격별 | F25: TON
B26: 이형철근(SD600) | C26: 규격별 | F26: TON
B27: 이형철근(SD400S) | C27: 규격별, 내진형 | F27: TON
B28: 이형철근(SD500S) | C28: 규격별, 내진형 | F28: TON
B29: 이형철근(SD600S) | C29: 규격별, 내진형 | F29: TON
B30: 철근공장가공 | F30: TON | G30: 공장가공일 경우 해당 (철근조립-건축(외주)) / 정미량(시공수량)
B31: SHOP DWG | F31: TON | G31: 공장가공일 경우 해당 (철근조립-건축(외주)) / 정미량(시공수량)
B32: 커플러(나사형/원터치형) | C32: 규격별 | F32: EA | G32: 커플러 할증없음
B34: 3. 벽돌류
B35: 시멘트벽돌 | C35: 190*90*57 | F35: 매 | G35: 할증 : 벽돌 3% 적용
G36: 분합문, 욕실문, 발코니문 하부 조적 : 매로 산출(쌓기물량제외) | L36: 개정
B37: 시멘트벽돌 | C37: 190*90*57, 욕조설치용 | F37: 매 | G37: 욕조설치용 : 세대당 30매 / 자재할증없음 (쌓기물량제외) | L37: 개정
B38: 시멘트블록 | C38: 4" | F38: 매 | G38: 할증 : 블록 4% 적용
B39: 시멘트블록 | C39: 6" | F39: 매
B40: 시멘트블록 | C40: 8" | F40: 매
B42: 4. 시멘트
B43: 시멘트 | C43: BULK, 파일용 | F43: TON | G43: 토목공사분
B44: 시멘트 | C44: BULK, 기포용 | F44: TON
B45: 시멘트 | C45: 40kg, 방수용 | F45: 포
B46: 시멘트 | C46: 40kg, 석재용 | F46: 포
...

Sheet 건축공사
A8: - 제 2 장 -
A16: 건축공사(외주)

Sheet 1.철콘
C2: 구분 | D2: 건축공사 | E2: 공종명 | G2: 1. 철근콘크리트공사 | H2: 개정 번호 | I2: REV.03 | J2: 제정일 | K2: =+개정내역!$O$4 -> 42697
J3: 개정일 | K3: =+개정내역!$N$4 -> 44748
B5: 품 명 | C5: 규 격 | F5: 단위 | G5: 주 요 내 용 | L5: 비 고
B6: ▶표준내역
B7: 1. 가설공사
B8: [아파트]
B9: 먹메김 | C9: 골조용 | F9: M2
B10: 강관동바리 | C10: 4.7M미만 | F10: M2 | N10: 강관동바리설치,해체?
B11: 조립식강관동바리 | C11: 지상층 | F11: 공M3 | N11: 시스템동바리설치해체?
B12: 시스템비계[분진망포함] | C12: 주출입구, 옥탑 | F12: M2
B13: 비계다리설치 | C13: 주출입구, 옥탑 | F13: 개소
B14: 현장정리비 | F14: M2
B16: [PIT,주차장,부대시설]
B17: 수평규준틀 | F17: M2
B18: 먹메김 | C18: 골조용 | F18: M2
B19: 강관동바리 | C19: 4.7M미만 | F19: M2
B20: 조립식강관동바리 | C20: 지하PIT,제연휀룸,부속동 | F20: 공M3
B21: 시스템비계[분진망포함] | C21: 부속동/근생 | F21: M2
B22: 시스템비계[분진망포함] | C22: 주차장외벽 | F22: M2
B23: JACK SUPPORT | C23: 15개월 | F23: EA
B24: 비계다리설치 | C24: 부속동 | F24: 개소
B25: P.E필름깔기 [자재포함] | C25: 0.03T 2겹 | F25: M2
B26: 현장정리비 | F26: M2
B28: 2. 거푸집공사
B29: [아파트]
B30: 거푸집설치및해체 | C30: 합판3회 | F30: M2 | G30: 알폼 및 데크플레이트 등을 제외한 모든 수평부재
B31: 거푸집설치및해체 | C31: 유로폼 | F31: M2 | G31: 알폼 수직부재를 제외한 모든 수직부재
B32: 거푸집설치및해체 | C32: 경사 | F32: M2 | G32: 램프 및 계단 경사, 옥탑 박공 지붕 등 경사부분에 적용
B33: 거푸집설치및해체 | C33: 층변화유로 | F33: M2 | G33: 층변화 3개층미만 구간
B34: 거푸집설치및해체 | C34: 피로티/합판 | F34: M2 | G34: 피로티 내 모든 수평부재
B35: 거푸집설치및해체 | C35: 피로티/유로 | F35: M2 | G35: 피로티 내 모든 수직부재
B36: 거푸집설치및해체 | C36: TG보 | F36: M2 | G36: 트렌스퍼 보 옆면
B37: 거푸집설치및해체 | C37: TP슬라브 | F37: M2 | G37: 트렌스퍼 슬라브 밑면
B38: 거푸집설치및해체 | C38: 피난층/합판 | F38: M2 | G38: 피난층 내 모든 수평부재
B39: 거푸집설치및해체 | C39: 피난층/유로 | F39: M2 | G39: 피난층 내 모든 수직부재(내측)
B40: 거푸집설치및해체 | C40: 옥탑거푸집 | F40: M2 | G40: 아파트 옥상층 모든 거푸집
B41: 거푸집설치및해체 | C41: 알폼수직(동바리설치해체포함) | F41: M2 | G41: 기준층+최상층 내부옹벽, 내부 인방보
... B45: 거푸집설치및해체 | C45: CS폼 | F45: M2 | G45: 기준층+최상층 외벽, 피난층 외벽, CS인양시스템 적용시
B46: 결로방지단열재타설부착[단열재별도] | C46: 10T, 압출법보온판(1호)/천정 | F46: M2
B47: 결로방지단열재타설부착[단열재별도] | C47: 10T, 압출법보온판(1호)/최상층 | F47: M2
...

Sheet 2.데크
C2: 구분 | D2: 건축공사 | E2: 공종명 | G2: 2. 데크플레이트공사 | H2: 개정 번호 | I2: REV.03 | J2: 제정일 | K2: =+개정내역!$O$4 -> 42697
J3: 개정일 | K3: =+개정내역!$N$4 -> 44748
B5: 품 명 | C5: 규 격 | F5: 단위 | G5: 주 요 내 용 | L5: 비 고
B6: ▶표준내역
B7: [PIT,주차장,부대시설]
B8: 데크플레이트 | C8: 규격별 | F8: M2
B9: 데크플레이트 설치 | C9: 청소비포함 | F9: M2 | G9: 비탈형, 일체형
B10: 데크플레이트 설치해체 | C10: 청소비포함 | F10: M2 | G10: 탈형
B12: [산출예시]
B13: 데크플레이트 | C13: ED1A-100 | F13: M2
G20: · <산출식>((단변-보폭)+0.05*2) X ((장변-보폭)+0.05*2)
G33: 철근은 현장배근만 산출
G34: → 연결근 / 보강근 / 배력근

Sheet 3.방수
C2: 구분 | D2: 건축공사 | E2: 공종명 | G2: 3. 방수공사 | H2: 개정 번호 | I2: REV.03 | J2: 제정일 | K2: =+개정내역!$O$4 -> 42697
J3: 개정일 | K3: =+개정내역!$N$4 -> 44748
B5: 품 명 | C5: 규 격 | F5: 단위 | G5: 주 요 내 용 | L5: 비 고
B6: ▶표준내역
B7: [아파트]
B8: 우레탄도막방수(APT지붕) | C8: 바닥, 비노출 | F8: M2
B9: 우레탄도막방수(APT지붕) | C9: 벽, 비노출 | F9: M2
B10: 지정복합방수(APT피로티) | C10: 바닥, 비노출 | F10: M2
B11: 액체방수 | C11: 2차, 단위세대 | F11: M2
B12: 액체방수 | C12: 2차, 공용부 | F12: M2
B13: 도막방수 | C13: 욕실, 발코니코너 | F13: M
B14: 보호몰탈 | C14: 바닥, 30T | F14: M2
B15: 보호몰탈 | C15: 벽, 18T | F15: M2
B16: 방수보호재 | C16: 바닥, 10T | F16: M2
B17: 방수보호재 | C17: 벽, 10T | F17: M2
B18: 쇠흙손마감 | C18: 방수바탕처리 | F18: M2
B19: 방수마감후레싱 | C19: 아파트 | F19: M
B21: [PIT,주차장,부대시설]
B22: 우레탄도막방수(부속동지붕) | C22: 바닥, 비노출 | F22: M2
B23: 우레탄도막방수(부속동지붕) | C23: 벽, 비노출 | F23: M2
B24: 지정복합시트방수(주차장지붕) | C24: 바닥, 비노출 | F24: M2
B25: 지정복합시트방수(주차장지붕) | C25: 벽, 비노출 | F25: M2
B26: 액체방수 | C26: 2차, 부속동 | F26: M2
B27: 액체방수 | C27: 2차, 지하PIT바닥 | F27: M2
B28: 액체방수 | C28: 2차, 지하PIT벽 | F28: M2
B29: 지정방수(실명) | C29: 바닥 | F29: M2
B30: 지정방수(실명) | C30: 벽 | F30: M2
B31: 지정방수(실명) | C31: 천정 | F31: M2
B32: 도막방수 | C32: 욕실, 발코니코너 | F32: M
B33: 보호몰탈 | C33: 바닥, 30T | F33: M2
... B39: 방수마감후레싱 | C39: 부속동 | F39: M
B41: ▶견적지침
B42: 우레탄도막방수 | F42: M2 | G42: 아파트 및 부속동 옥상층 우레탄도막방수적용(비노출, 3T)
G43: 지하외벽 도막방수는 별도계상 안함
G44: 아파트 및 부속동 지붕 감아올림높이는 무근Con'c높이까지 산출 | L44: 개정 | M44: 23.04.17
B45: 지정복합방수 | F45: M2 | G45: 피로티 바닥 및 벽 산출
B46: 지정복합시트방수 | F46: M2 | G46: 지하주차장 상부 바닥 및 벽 산출
G47: 도막+시트방수 공법으로 도막(2T)+시트(2T) 적용
G48: 방수올림(벽)은 H:1,200 (단, 도면과 산출기준이 상이할경우 도면우선적용)
G49: 방수내림(벽)은 H:1,000 적용
...

Sheet 4.견출
C2: 구분 | D2: 건축공사 | E2: 공종명 | G2: 4. 견출공사 | H2: 개정 번호 | I2: REV.03 | J2: 제정일 | K2: =+개정내역!$O$4 -> 42697
J3: 개정일 | K3: =+개정내역!$N$4 -> 44748
B5: 품 명 | C5: 규 격 | F5: 단위 | G5: 주 요 내 용 | L5: 비 고
B6: ▶표준내역
B7: [아파트]
B8: 콘크리트면처리 | C8: 내벽 | F8: M2
B9: [물량산출]
B10: 콘크리트면처리 | C10: 내벽/벽지 | F10: M2 | G10: 부위별 산출
B11: 콘크리트면처리 | C11: 발코니벽 | F11: M2 | G11: 부위별 산출
B12: 콘크리트면처리 | C12: 내천정 | F12: M2
B13: [물량산출]
B14: 콘크리트면처리 | C14: 발코니천정 | F14: M2 | G14: 부위별 산출
B15: 콘크리트면처리 | C15: 계단실천정 | F15: M2 | G15: 부위별 산출
B16: 콘크리트면처리 | C16: 외벽 | F16: M2
B17: [물량산출]
B18: 콘크리트면처리 | C18: 외벽(갱폼)/수성페인트 | F18: M2 | G18: 부위별 산출
B19: 콘크리트면처리 | C19: 외벽(저층부)/석재뿜칠 | F19: M2 | G19: 부위별 산출
B20: 콘크리트면처리 | C20: 외벽(피로티)/석재뿜칠 | F20: M2 | G20: 부위별 산출
B21: 콘크리트면처리 | C21: 외천정 | F21: M2
B22: 콘크리트면처리 | C22: 계단실벽 | F22: M2
B23: 수지미장 | C23: 계단실벽, E/V HALL(부자재포함) | F23: M2
B24: 수지미장 | C24: 발코니벽(부자재포함) | F24: M2
B26: [PIT,주차장,부대시설]
B27: 콘크리트면처리 | C27: 내벽 | F27: M2
B28: 콘크리트면처리 | C28: 내천정 | F28: M2
B29: 콘크리트면처리 | C29: 외벽 | F29: M2
B30: 콘크리트면처리 | C30: 외천정 | F30: M2
B31: 수지미장 | C31: 계단실벽, E/V HALL(부자재포함) | F31: M2
B41: ▶견적지침
B42: 콘크리트면처리 | C42: 내벽 | F42: M2 | G42: 콘크리트면 위 도배 또는 도장 마감일 경우 산출
G43: 세대내부 : 도배 또는 도장마감일 경우 산출
G44: 산출높이 : 천정마감 있는 경우 - 천정고 + 0.1m | L44: 개정
G45: 산출높이 : 천정마감 없는 경우 - 층고 - SLAB두께
B46: 콘크리트면처리 | C46: 내천정 | F46: M2 | G46: 지하주차장 천정 뿜칠일 경우 미산출
B47: 콘크리트면처리 | C47: 외벽 | F47: M2 | G47: 외벽마감 석재일 경우 미산출
B48: 콘크리트면처리 | C48: 외천정 | F48: M2
B49: 콘크리트면처리 | C49: 계단실벽 | F49: M2 | G49: 4F~최상층 계단실벽 산출 | L49: 개정
B50: 수지미장 | C50: 계단실벽, E/V HALL(부자재포함) | F50: M2 | G50: 도면에 별도 명기가 없더라도 계단실(1~3F) 및 E/V홀 벽 적용(자체현장) | L50: 개정
G51: (부자재는 지입자재로 단가포함)
B52: 수지미장 | C52: 발코니벽(부자재포함) | F52: M2 | G52: 도면에 별도 명기가 없더라도 세대발코니 벽 적용(자체현장) | L52: 개정

Sheet 5.조적
C2: 구분 | D2: 건축공사 | E2: 공종명 | G2: 5. 조적공사 | H2: 개정 번호 | I2: REV.03 | J2: 제정일 | K2: =+개정내역!$O$4 -> 42697
J3: 개정일 | K3: =+개정내역!$N$4 -> 44748
B5: 품 명 | C5: 규 격 | F5: 단위 | G5: 주 요 내 용 | L5: 비 고
B6: ▶표준내역
B7: [아파트]
B8: 시멘트벽돌쌓기 | C8: 0.5B | F8: 천매
B9: 시멘트벽돌쌓기 | C9: 1.0B | F9: 천매
B10: 시멘트벽돌세워쌓기 | C10: 0.5B | F10: 천매
B11: 벽돌소운반 | F11: 천매
B12: ALC블록쌓기 | C12: 두께별, 자재포함 | F12: M2
B13: 인방제작설치 | C13: 0.5B,부자재포함 | F13: M
B14: 인방제작설치 | C14: 1.0B,부자재포함 | F14: M
B15: 단열재공간넣기[단열재별도] | C15: 두께별, 단열재종류(호수) | F15: M2
B16: 단열재붙이기/AD,PD속 [단열재별도] | C16: 두께별, 단열재종류(호수) | F16: M2
B18: [PIT,주차장,부대시설]
B19: 시멘트벽돌쌓기 | C19: 0.5B | F19: 천매
B20: 시멘트벽돌쌓기 | C20: 1.0B | F20: 천매
B21: 벽돌소운반 | F21: 천매
B22: 시멘트블록보강쌓기(사춤1종) | C22: 6" 일면치장 | F22: M2
B23: 시멘트블록보강쌓기(사춤1종) | C23: 6" 양면치장 | F23: M2
B24: 시멘트블록보강쌓기(사춤1종) | C24: 8" 일면치장 | F24: M2
B25: 시멘트블록보강쌓기(사춤1종) | C25: 8" 양면치장 | F25: M2
B26: 시멘트블록보강쌓기(사춤1종) | C26: 8" | F26: M2
B27: 인방제작설치 | C27: 0.5B,부자재포함 | F27: M
B28: 인방제작설치 | C28: 1.0B,부자재포함 | F28: M
B29: 인방제작설치 | C29: 6" | F29: M
B30: 인방제작설치 | C30: 8" | F30: M
B31: 적(치장)벽돌 치장쌓기 | C31: 0.5B | F31: 천매
B32: 적(치장)벽돌 치장쌓기 | C32: 1.0B | F32: 천매
B33: 단열재공간넣기[단열재별도] | C33: 두께별, 단열재종류(호수) | F33: M2
B34: 단열재붙이기/AD,PD속[단열재별도] | C34: 두께별, 단열재종류(호수) | F34: M2
B41: ▶견적지침
B42: 시멘트벽돌쌓기 | F42: 천매 | G42: 높이산출 : 층고 - 슬라브두께 (슬라브하부선까지) | L42: 개정
G43: [매수환산기준]
G44: 0.5B : 75장/M2 / 1.0B : 149장/M2 / 1.5B : 224장/M2
G45: 욕조설치용/분합문, 욕실문, 발코니문 하부 조적 : 쌓기물량제외 | L45: 개정
B46: 시멘트벽돌세워쌓기 | F46: 천매 | G46: 벽돌세워쌓기 : 50장/M2
B47: 벽돌소운반 | F47: 천매 | G47: 벽돌쌓기 매수와 동일
B48: ALC블록쌓기 | F48: M2
B49: 인방제작설치 | F49: M | G49: 개구부폭 + (0.2X2(좌,우 여장))
...

Sheet 6.미장
C2: 구분 | D2: 건축공사 | E2: 공종명 | G2: 6. 미장공사 | H2: 개정 번호 | I2: REV.03 | J2: 제정일 | K2: =+개정내역!$O$4 -> 42697
J3: 개정일 | K3: =+개정내역!$N$4 -> 44748
B5: 품 명 | C5: 규 격 | F5: 단위 | G5: 주 요 내 용 | L5: 비 고
B6: ▶표준내역
B7: [아파트] | O7: 구분 | P7: 종류 | Q7: 사춤 | R7: 적용부위 | S7: 비고
B8: 경량기포콘크리트 | C8: 두께별 | F8: M3 | O8: 세대 | P8: AG | Q8: 몰탈 | R8: 하부1면 | S8: 미장공사
B9: 방바닥미장 | C9: 30T, 현관디딤판하부 | F9: M2 | Q9: 우레아폼 | R9: 3면 | S9: AL창호공사
B10: 방바닥미장 | C10: 40T | F10: M2 | P10: PD/PW | Q10: 몰탈 | R10: 하부1면 | S10: 미장공사
B11: 방바닥미장 | C11: 120T, 신발장하부 | F11: M2 | Q11: 우레아폼 | R11: 3면 | S11: PL창호공사
B12: 시멘트몰탈 | C12: 9T, 벽초벌 | F12: M2 | P12: WD-옹벽 | Q12: 몰탈 | R12: 3면 | S12: 미장공사
B13: 시멘트몰탈 | C13: 18T, 내벽 | F13: M2 | P13: WD-건식벽 | Q13: 우레아폼 | R13: 상부1면 | S13: 미장공사
B14: 시멘트몰탈 | C14: 24T, 외벽 | F14: M2 | Q14: 우레아폼 | R14: 좌,우 2면 | S14: 목창호공사
B15: 계단마구리미장 | C15: W150~300 | F15: M | P15: WPD | Q15: WD와 동일
B16: 걸레받이몰탈 | C16: 발코니 H100 | F16: M | P16: FSD/SD | Q16: 몰탈 | R16: 4면 | S16: 미장공사
B17: 쇠흙손마감 | C17: 무근면 | F17: M2 | O17: 공용부 /부대시설 | P17: AG/AW | Q17: 몰탈 | R17: 하부1면 | S17: 미장공사
B18: 쇠흙손마감 | C18: 골조면 | F18: M2 | Q18: 우레아폼 | R18: 3면 | S18: AL창호공사
B19: 신축줄눈(SAW CUTTING) | C19: 코킹포함 | F19: M | P19: PD/PW | Q19: 몰탈 | R19: 하부1면 | S19: 미장공사
B20: 걸레받이비드 | F20: M | Q20: 우레아폼 | R20: 3면 | S20: PL창호공사
B21: ELEV주위사춤및미장 | C21: 몰탈사춤 | F21: M | P21: WD-옹벽 | Q21: 몰탈 | R21: 3면 | S21: 미장공사
B22: 창틀,문틀주위사춤 | C22: 몰탈사춤 | F22: M | P22: WD-건식벽 | Q22: 우레아폼 | R22: 상부1면 | S22: 미장공사
B23: [물량산출] | Q23: 우레아폼 | R23: 좌,우 2면 | S23: 목창호공사
B24: 창틀,문틀주위사춤 | C24: 몰탈사춤(AL) | F24: M | G24: 창호별 산출 | P24: WPD | Q24: WD와 동일
B25: 창틀,문틀주위사춤 | C25: 몰탈사춤(PL) | F25: M | G25: 창호별 산출
B26: 창틀,문틀주위사춤 | C26: 몰탈사춤(SD) | F26: M | G26: 창호별 산출
B27: 창틀,문틀주위사춤 | C27: 몰탈사춤(SSD) | F27: M | G27: 창호별 산출
B28: 창틀,문틀주위사춤 | C28: 몰탈사춤(WD) | F28: M | G28: 창호별 산출
B29: 세대내 미장보수 | C29: 30평대 미만 | F29: 세대
B30: 세대내 미장보수 | C30: 30평대 이상 | F30: 세대
B41: [PIT,주차장,부대시설]
B42: 경량기포콘크리트 | C42: 두께별 | F42: M3
B43: 방바닥미장 | C43: 40T | F43: M2
B44: 시멘트몰탈 | C44: 바닥 | F44: M2
B45: [물량산출]
B46: 시멘트몰탈 | C46: 바닥, 두께별 | F46: M2 | G46: 두께별 산출
B47: 시멘트몰탈 | C47: 9T, 벽초벌 | F47: M2
B48: 시멘트몰탈 | C48: 18T, 내벽 | F48: M2
B49: 시멘트몰탈 | C49: 24T, 외벽 | F49: M2
B50: 계단마구리미장 | C50: W=150~300 | F50: M
B51: 쇠흙손마감 | C51: 무근면 | F51: M2
B52: 쇠흙손마감 | C52: 골조면 | F52: M2
...

Sheet 7.타일
C2: 구분 | D2: 건축공사 | E2: 공종명 | G2: 7. 타일공사 | H2: 개정 번호 | I2: REV.03 | J2: 제정일 | K2: =+개정내역!$O$4 -> 42697
J3: 개정일 | K3: =+개정내역!$N$4 -> 44748
B5: 품 명 | C5: 규 격 | F5: 단위 | G5: 주 요 내 용 | L5: 비 고
B6: ▶표준내역
B7: [아파트]
B8: 현관바닥타일붙이기 | C8: 크기(000*000) | F8: M2
B9: 현관창고바닥타일붙이기 | C9: 크기(000*000) | F9: M2
B10: 공용욕실바닥타일붙이기 | C10: 크기(000*000) | F10: M2
B11: 공용욕실벽타일붙이기 | C11: 떠붙이기/크기(000*000) | F11: M2
B12: 부부욕실바닥타일붙이기 | C12: 크기(000*000) | F12: M2
B13: 부부욕실벽타일붙이기 | C13: 떠붙이기/크기(000*000) | F13: M2
B14: 주방벽타일붙이기 | C14: 본드/크기(000*000) | F14: M2
B15: 거실벽타일붙이기 | C15: 본드(에폭시)/크기(000*000), 부자재포함 | F15: M2
B16: 발코니바닥타일붙이기 | C16: 크기(000*000) | F16: M2
B17: 거실/주방바닥타일붙이기 | C17: 압착, 판넬히팅면 | F17: M2
B18: 홀바닥타일붙이기 | C18: ELEV홀 | F18: M2
B19: 폴리싱타일벽붙이기 | C19: ELEV홀/동출입구, 부자재포함 | F19: M2
... B24: 장애인점자블럭 | C24: 300*300, 타일용 | F24: EA
B25: 공용욕실벽타일코너비드 | F25: M
B26: 부부욕실벽타일코너비드 | F26: M
B27: 거실아트월벽타일코너비드 | F27: M
B28: 타일벽코너비드설치 | C28: SST, 30*30, ELEV.홀 | F28: M
B29: 인조대리석재료분리대/평형별(시공) | C29: 실별, L(길이)*W(폭)*H(높이) | F29: M
B30: 인조대리석샤워부스씰/평형별(시공) | C30: 실별, L(길이)*W(폭)*H(높이) | F30: M
B31: [물량산출]
B32: 인조대리석재료분리대/84A(시공) | C32: 욕실도어하부, L750*W52*H75, [LG]G038 시오트쿼츠 | F32: M | G32: 재료등급 기입
B33: 타일시멘트 | C33: 붙임용, 25kg/포 | F33: 포
B34: 백시멘트 | C34: 메지용, 40kg/포 | F34: 포
B35: 타일본드 | C35: CERAFIX | F35: KG
B36: 타일면보양 | F36: M2
B41: [PIT,주차장,부대시설]
B42: 부속동바닥타일붙이기 | F42: M2
B43: [물량산출]
B44: 부속동바닥타일붙이기 | C44: 60T | F44: M2 | G44: 두께별 산출
B45: 부속동벽타일붙이기 | C45: 떠붙이기 | F45: M2
B46: 부속동벽타일붙이기 | C46: 본드 | F46: M2
B47: 계단바닥타일붙이기 | C47: 두께별 | F47: M2
B48: 계단(디딤판)타일붙이기 | C48: W(폭)*두께별 | F48: M2
B49: 계단(챌판)타일붙이기 | C49: 두께별 | F49: M2
B50: 타일바탕몰탈 | C50: 내벽, 15T, 떠붙임/욕실 | F50: M2
...

Sheet 8.석
C2: 구분 | D2: 건축공사 | E2: 공종명 | G2: 8. 석공사 | H2: 개정 번호 | I2: REV.03 | J2: 제정일 | K2: =+개정내역!$O$4 -> 42697
J3: 개정일 | K3: =+개정내역!$N$4 -> 44748
B5: 품 명 | C5: 규 격 | F5: 단위 | G5: 주 요 내 용 | L5: 비 고
B6: ▶표준내역
B7: [아파트]
B8: 석재면보양 | C8: 바닥,디딤판 | F8: M2
B9: 지정석재마감(바닥) | C9: 부위/두께별, 몰탈(두께별) | F9: M2
B10: 지정석재마감(계단) | C10: 바닥/두께별, ,몰탈(두께별) | F10: M2
B11: 지정석재마감(계단) | C11: 디딤판/W(폭)*두께별, 몰탈(두께별) | F11: M2
B12: 지정석재마감(계단) | C12: 챌판/H(높이)*두께별, 몰탈(두께별) | F12: M2
B13: 피로티지정마감(바닥) | C13: 부위/두께별, 몰탈(두께별) | F13: M2
B14: 지정석재마감(외벽) | C14: APT(저층부) | F14: M2
B15: 지정석재마감(외벽) | C15: 피로티 | F15: M2
B16: 지정석재마감(외벽) | C16: 주출입구 | F16: M2
B17: 시스템비계 | C17: 마감용, 아파트(저층부) | F17: M2
B18: 장애인점자블럭 | C18: 300*300,석재면 | F18: EA
B19: 단열재붙이기 [단열재별도] | C19: 두께별, 단열재종류(호수) | F19: M2
B20: 재료분리대(강마루+디딤판) | C20: T=3,황동 | F20: M
B21: ※세대 및 부속동의 현관디딤판, 굽도리, 걸레받이, 욕실선반, 화장대상판 등 인조석공사 관련항목은 자재납품으로 공종이동 | L21: 개정
B22: [PIT,주차장,부대시설]
B23: 석재면보양 | C23: 바닥,디딤판 | F23: M2
B24: 지정석재마감(바닥) | C24: 부위/두께별, 몰탈(두께별) | F24: M2
B25: 지정석재마감(계단) | C25: 바닥/두께별, ,몰탈(두께별) | F25: M2
B26: 지정석재마감(계단) | C26: 디딤판/W(폭)*두께별, 몰탈(두께별) | F26: M2
B27: 지정석재마감(계단) | C27: 챌판/H(높이)*두께별, 몰탈(두께별) | F27: M2
B28: 지정석재마감(외벽) | C28: 부속동 | F28: M2
B29: [물량산출]
B30: 지정석재마감(외벽) | C30: 주차장램프 | F30: M2
B31: 지정석재마감(외벽) | C31: 옥외송수구 | F31: M2
B32: 지붕난간두겁대 | C32: W(폭)*두께별, 파라펫/부속동 | F32: M
B33: 화강석창대석 | C33: W(폭)*두께별,부위 | F33: M
B34: 마블세면대 | C34: W(폭) | F34: M
B35: 문주/주출입구 | C35: L(길이)*W(폭)*H(높이),구체및마감일체포함 | F35: EA
B36: 문주/램프출입구 | C36: L(길이)*W(폭)*H(높이),구체및마감일체포함 | F36: EA
B37: 시스템비계 | C37: 마감용, 부속동 | F37: M2
B38: 장애인점자블럭 | C38: 300*300,석재면 | F38: EA
B39: 단열재붙이기 [단열재별도] | C39: 두께별, 단열재종류(호수) | F39: M2
B41: ▶견적지침
B42: 지정석재마감(바닥) | F42: M2 | G42: ※자체공사 : 도면에 별도 명기가 없어도 지하, 지상1층 진입홀 바닥 석재 적용
B43: 지정석재마감(계단) | F43: M2 | G43: 시공부위별 산출(바닥/디딤판/챌판)
...

Sheet 9.테라죠
C2: 구분 | D2: 건축공사 | E2: 공종명 | G2: 9. 테라죠공사 | H2: 개정 번호 | I2: REV.03 | J2: 제정일 | K2: =+개정내역!$O$4 -> 42697
J3: 개정일 | K3: =+개정내역!$N$4 -> 44748
B5: 품 명 | C5: 규 격 | F5: 단위 | G5: 주 요 내 용 | L5: 비 고
B6: ▶표준내역
B7: [PIT,주차장,부대시설]
B8: 테라죠(바닥) | C8: 두께별, 몰탈(두께별) | F8: M2
B9: 테라죠(디딤판) | C9: 두께별, 몰탈(두께별) | F9: M2
B10: 테라죠(챌판) | C10: 두께별, 몰탈(두께별) | F10: M2
B11: 테라죠보양 | F11: M2 | G11: 계단챌판 면적을 제외한 전체면적 산출

Sheet 10.금속,금속창호
C2: 구분 | D2: 건축공사 | E2: 공종명 | G2: 10. 금속,금속창호공사 | H2: 개정 번호 | I2: REV.03 | J2: 제정일 | K2: =+개정내역!$O$4 -> 42697
J3: 개정일 | K3: =+개정내역!$N$4 -> 44748
B5: 품 명 | C5: 규 격 | F5: 단위 | G5: 주 요 내 용 | L5: 비 고
B6: ▶표준내역
B7: [아파트]
B8: SST선홈통 | C8: 규격별 | F8: M
B9: 상자홈통 | C9: SST/크기(000*000) | F9: EA
B10: 빗물받이블럭 | F10: EA
B11: 주철제루프드레인설치 | C11: 규격별 | F11: EA
B12: 장애자램프핸드레일 | C12: 부위/ H(높이) | F12: M
B13: 동출입구핸드레일 | C13: 부위/ H(높이) | F13: M
B14: 지붕안전난간대 | C14: H(높이) | F14: M
B15: 옥탑점검사다리(외부용) | C15: W(폭), H(높이) | F15: EA
B16: 집수정뚜껑 | C16: 크기(000*000) | F16: EA
B17: 청소용고리 설치 | F17: EA
B18: SST재료분리대 | F18: M
B19: PD.COVER | C19: STL 1.6T, 점검구 포함 | F19: M2 | G19: 산출된 개소물량 M2로 환산하여 반영
B20: [물량산출]
B21: PD.COVER(PS/AV)/78A+78B+78A | C21: (390+3860+390)*4820, 점검구포함 | F21: EA
B22: 설비점검구 | C22: 부위/크기(000*000) | F22: EA
B23: 전기점검구 | C23: 부위/크기(000*000) | F23: EA
B24: 핸드레일촉지판-인쇄+점자타공 | F24: EA
B25: 무동력흡출기 | C25: 규격(D000), 좌대포함 | F25: EA
B26: 자전거보관소 | C26: 보관대수/내부 | F26: 개소
B27: 자전거보관소 | C27: 보관대수/외부(지붕일체포함) | F27: 개소
B28: 쓰레기분리수거장 | C28: 크기(000*000),지붕/바닥마감 포함 | F28: EA
B29: 쓰레기분리수거함 | C29: 용도별/용량 | F29: EA
B30: 출입구캐노피(APT) | C30: L(길이)*W(폭)*H(높이), 마감재 및 포함사항 | F30: 개소
B31: ASD/부위 | C31: 규격별/자동문 및 FIX유리포함 | F31: 개소
B32: FSD(SD)/부위[점검구] | C32: 규격별 | F32: 개소
B33: 알루미늄시트커버 붙이기 | C33: 층변화구간(H600) | F33: M2
B34: 음식물처리종량시스템 | C34: RFID시스템 | F34: EA | G34: 해당현장에 한함
B37: [PIT,주차장,부대시설]
B38: SST선홈통 | C38: 규격별 | F38: M
B39: 상자홈통 | C39: SST/크기(000*000) | F39: EA
B40: 빗물받이블럭 | F40: EA
B41: 주철제루프드레인설치 | C41: 규격별 | F41: EA
B42: 지붕안전난간대 | C42: H(높이) | F42: M
B43: 기계/전기실계단핸드레일 | C43: H(높이) | F43: M
B44: 부속동계단핸드레일 | C44: H(높이) | F44: M
...

Sheet 11.AL창호
C2: 구분 | D2: 건축공사 | E2: 공종명 | G2: 11. AL창호공사 | H2: 개정 번호 | I2: REV.03 | J2: 제정일 | K2: =+개정내역!$O$4 -> 42697
J3: 개정일 | K3: =+개정내역!$N$4 -> 44748
B5: 품 명 | C5: 규 격 | F5: 단위 | G5: 주 요 내 용 | L5: 비 고
B6: ▶표준내역
B7: [아파트]
B8: AG/실명 | C8: 규격별 | F8: EA
B9: AW/실명 | C9: 규격별 | F9: EA
B10: AGW/실명 | C10: 규격별 | F10: EA
B11: AG/평형/실외기실 | C11: 규격별 | F11: EA
B12: CAW/부위 | C12: 규격별 | F12: EA
B13: 롤방충망(PJ전용) | F13: M2
B14: 창호코킹(AL창호) | C14: 10*10 | F14: M
B15: 창틀,문틀주위사춤 | C15: 우레아폼(AL창호) | F15: M
B17: [PIT,주차장,부대시설]
B18: AW/부속동/실명 | C18: 규격별 | F18: EA
B19: AD/부속동/실명 | C19: 규격별 | F19: EA
B20: AG/부속동/실명 | C20: 규격별 | F20: EA
B21: CAW/부위 | C21: 규격별 | F21: EA
B22: 롤방충망(PJ전용) | F22: M2
B23: 창호코킹(AL창호) | C23: 10*10 | F23: M
B24: 창틀,문틀주위사춤 | C24: 우레아폼(AL창호) | F24: M
B41: ▶견적지침
B42: AG | F42: EA
B43: AD | F43: EA | G43: 유리도어 있을 경우 유리도어/플로어힌지 미산출
B44: AW | F44: EA | G44: 계단실부위 자동개폐장치 창호와 별도산출
B45: AGW | F45: EA
B46: CAW/부위 | F46: EA | G46: 금속공사 : 백판넬/층간방화구획
G47: 유리공사 : 웨더실/구조용코킹/노턴테이프
B48: 롤방충망(PJ전용) | F48: M2 | G48: 미서기방충망은 별도산출하지 않음(창호포함)
B49: 창호코킹(AL창호) | F49: M
B50: 창틀,문틀주위사춤 | C50: 우레아폼(AL창호) | F50: M | G50: 상부/양옆면은 우레아폼사춤, 하부는 몰탈사춤(미장공사)
G52: ※ AL창호의 유리도어/플로어힌지는 창호에 포함으로 미산출 | L52: 개정
G53: ※ 금속 SSD창호의 유리도어/플로어힌지 별도산출 | L53: 개정
G54: ※ 산출예시
H55: ① 창호사춤/우레아폼 : W+(H*2) (m)
H56: ② 창호사춤/몰탈 : W (m)
H57: ③ 창호코킹 : (W＋H)*2*2면 (m)
H58: ④ 유리 : W*H (m2)
H59: ⑤ 유리끼우고 닦기 : W*H (m2)
H60: ⑥ 유리코킹 : (W*8＋H*2)*2면 (m)
...

Sheet 12.PL창호
C2: 구분 | D2: 건축공사 | E2: 공종명 | G2: 12. PL창호공사 | H2: 개정 번호 | I2: REV.03 | J2: 제정일 | K2: =+개정내역!$O$4 -> 42697
J3: 개정일 | K3: =+개정내역!$N$4 -> 44748
B5: 품 명 | C5: 규 격 | F5: 단위 | G5: 주 요 내 용 | L5: 비 고
B6: ▶표준내역
B7: 14-01.PL창호공사(기본)
B8: [아파트]
B9: PD(단창)/부위/평형별 | C9: 규격별 | F9: EA
B10: PD(이중창)/부위/평형별 | C10: 규격별 | F10: EA
B11: PD(터닝도어)/부위/평형별 | C11: 규격별 | F11: EA
B12: PW(단창)/부위/평형별 | C12: 규격별 | F12: EA
B13: PW(이중창)/부위/평형별 | C13: 규격별 | F13: EA
B14: PG/부위/평형별 | C14: 규격별 | F14: EA
B15: 창호코킹(PL창호)/내부 | C15: 10*10 | F15: M
B16: 창호코킹(PL창호)/외부 | C16: 10*10 | F16: M
B17: 창틀,문틀주위사춤 | C17: 우레아폼(PL창호) | F17: M
B19: [PIT,주차장,부대시설]
B20: PD(단창)/부위 | C20: 규격별 | F20: EA
B21: PD(이중창)/부위 | C21: 규격별 | F21: EA
B22: PD(터닝도어)/부위 | C22: 규격별 | F22: EA
B23: PW(단창)/부위 | C23: 규격별 | F23: EA
B24: PW(이중창)/부위 | C24: 규격별 | F24: EA
B25: PG/부위 | C25: 규격별 | F25: EA
B26: 창호코킹(PL창호)/내부 | C26: 10*10 | F26: M
B27: 창호코킹(PL창호)/외부 | C27: 10*10 | F27: M
B28: 창틀,문틀주위사춤 | C28: 우레아폼(PL창호) | F28: M
B41: 14-02.PL창호공사(확장)
B42: [아파트]
B43: PD(단창)/부위/평형별 | C43: 규격별 | F43: EA
B44: PD(이중창)/부위/평형별 | C44: 규격별 | F44: EA
B45: PD(터닝도어)/부위/평형별 | C45: 규격별 | F45: EA
B46: PW(단창)/부위/평형별 | C46: 규격별 | F46: EA
B47: PW(이중창)/부위/평형별 | C47: 규격별 | F47: EA
B48: PG/부위/평형별 | C48: 규격별 | F48: EA
B49: 창호코킹(PL창호)/내부 | C49: 10*10 | F49: M
B50: 창호코킹(PL창호)/외부 | C50: 10*10 | F50: M
B51: 창틀,문틀주위사춤 | C51: 우레아폼(PL창호) | F51: M
B52: 분합창손잡이설치 | F52: EA
B76: ▶견적지침
B77: PD/PW/PG | F77: EA | G77: 단창/이중창/터닝도어 구분 표기
B78: 창호코킹(PL창호)/내부 | C78: 10*10 | F78: M | G78: 외벽 바깥면을 제외한 모든 부위를 내부로 산출
...

Sheet 13.유리
C2: 구분 | D2: 건축공사 | E2: 공종명 | G2: 13. 유리공사 | H2: 개정 번호 | I2: REV.03 | J2: 제정일 | K2: =+개정내역!$O$4 -> 42697
J3: 개정일 | K3: =+개정내역!$N$4 -> 44748
B5: 품 명 | C5: 규 격 | F5: 단위 | G5: 주 요 내 용 | L5: 비 고
B6: ▶표준내역
B7: 15-01.유리공사(기본)
B8: [아파트]
B9: 투명유리 | C9: 두께별 | F9: M2
B10: 컬러유리 | C10: 두께별 | F10: M2
B11: 방화유리 | C11: 두께별 | F11: M2
B12: 강화유리 | C12: 두께별 | F12: M2
B13: 복층유리 | C13: 두께별 | F13: M2
B14: 로이복층유리 | C14: 두께별 | F14: M2
B15: [산출예시]
B16: 로이복층유리 | C16: 24MM(5LE+14Air+5CL) | F16: M2
B17: 로이(아르곤)복층유리 | C17: 두께별 | F17: M2
B18: 유리끼우고닦기 | C18: 10MM미만 | F18: M2
B19: 유리끼우고닦기 | C19: 10MM이상 | F19: M2
B20: 유리끼우고닦기 | C20: 복층유리 | F20: M2
B21: 유리코킹 | C21: 5*5 | F21: M
B23: [PIT,주차장,부대시설]
B24: 투명유리 | C24: 두께별 | F24: M2
B25: 컬러유리 | C25: 두께별 | F25: M2
B26: 방화유리 | C26: 두께별 | F26: M2
B27: 강화유리 | C27: 두께별 | F27: M2
B28: 복층유리 | C28: 두께별 | F28: M2
B29: 로이복층유리 | C29: 두께별 | F29: M2
B30: 로이(아르곤)복층유리 | C30: 두께별 | F30: M2
B31: 유리끼우고닦기 | C31: 10MM미만 | F31: M2
B32: 유리끼우고닦기 | C32: 10MM이상 | F32: M2
B33: 유리끼우고닦기 | C33: 복층유리 | F33: M2
B34: 유리코킹 | C34: 5*5 | F34: M
B35: 방습거울 | C35: 규격별 ,부위/틀,코킹포함 | F35: EA
B36: ※ 커튼월공사 추가항목
B37: 웨더실 | F37: M
B38: 구조용코킹 | F38: M
B39: 노턴테이프 | F39: M
B41: 15-02.유리공사(확장)
B42: [아파트]
B43: 투명유리 | C43: 두께별 | F43: M2
B44: 컬러유리 | C44: 두께별 | F44: M2
...

Sheet 14.내장목
C2: 구분 | D2: 건축공사 | E2: 공종명 | G2: 14. 내장목공사 | H2: 개정 번호 | I2: REV.03 | J2: 제정일 | K2: =+개정내역!$O$4 -> 42697
J3: 개정일 | K3: =+개정내역!$N$4 -> 44748
B5: 품 명 | C5: 규 격 | F5: 단위 | G5: 주 요 내 용 | L5: 비 고
B6: ▶표준내역
B7: [아파트]
B8: 먹매김 | C8: 마감용 | F8: M2
B9: 경량철골천정틀 | C9: 세대내, M-BAR, H(높이) | F9: M2
B10: 경량철골천정틀/최상층 | C10: 세대내, M-BAR, H(높이) | F10: M2
B11: 경량철골천정틀/최상층발코니 | F11: M2
B12: 석고보드붙이기[자재포함] | C12: 9.5T,천정 | F12: M2
B13: 석고보드붙이기[자재포함] | C13: 9.5T,현관문주위 | F13: M2
B14: 우물천정설치/평형별 | C14: 실명/크기(000*000)/몰딩포함 | F14: 개소
B15: 시트판넬설치/평형별 | C15: 실명/크기(000*000)/알판+지정시트 | F15: 개소
B16: 커텐박스설치 | C16: 합판+석고/W(폭)*H(높이) | F16: M
B17: 침실몰딩 | C17: 재질(PVC)/크기 | F17: M
B18: 거실몰딩 | C18: 재질(PVC)/크기 | F18: M
B19: 최상층발코니천정몰딩 | C19: 재질(PVC) | F19: M
B20: 걸레받이 | C20: 재질(PVC)/크기 | F20: M
B21: 합지판설치 [단열재별도] | C21: 단열재,T(두께)+(방수)석고보드9.5T | F21: M2
B22: 경량칸막이 | C22: T(두께)/STUD+GW+석고9.5T 양면2P | F22: M2
B23: [물량산출]
B24: 경량칸막이/평형별 | C24: 침실2,3/L3780*H2590*130T/ 도어(900*2100*2)공제/ STUD+GW+석고9.5T 양면2P | F24: EA | G24: 평형별, 실별 물량산출
B25: 건식칸막이 | C25: 두께별/STUD+석고9.5T 양면2P | F25: M2
B26: 경량철골천정틀 | C26: M-BAR 1M이하 | F26: M2
B27: 석고보드붙이기[자재포함] | C27: ELEV홀/9.5T+12.5T,천정 | F27: M2
B28: PVC천정재 | C28: 부위/천정틀,점검구,몰딩포함 | F28: M2
B29: SMC천정재 | C29: 부위/천정틀,점검구,몰딩포함 | F29: M2
B30: AL천정재 | C30: 부위/천정틀,점검구,몰딩포함 | F30: M2
B31: AL천정몰딩 | C31: 공용부 | F31: M
B32: 커텐박스설치 | C32: 공용부 | F32: M
B33: 흡음천정설치 | C33: EV기계실, G/W50MM+G/C | F33: M2
B34: 흡음벽체설치 | C34: EV기계실, G/W50MM+G/C | F34: M2
B40: [PIT,주차장,부대시설]
B41: 먹매김 | C41: 마감용 | F41: M2
B42: 걸레받이 | C42: 재질/H(높이) | F42: M
B43: 합지판설치 [단열재별도] | C43: 단열재종류(호수) 두께+(방수)석고보드9.5T | F43: M2
B44: 경량칸막이 | C44: 두께별 | F44: M2
B45: DRY WALL | C45: 두께별 | F45: M2
B46: 경량철골천정틀 | C46: M-BAR 높이별 | F46: M2 | G46: 1M미만, 1~2M이하 등 1M 높이구간별 산출
B47: 석고보드붙이기 | C47: 9.5T | F47: M2
...

Sheet 15.목창호
C2: 구분 | D2: 건축공사 | E2: 공종명 | G2: 15. 목창호공사 | H2: 개정 번호 | I2: REV.03 | J2: 제정일 | K2: =+개정내역!$O$4 -> 42697
J3: 개정일 | K3: =+개정내역!$N$4 -> 44748
B5: 품 명 | C5: 규 격 | F5: 단위 | G5: 주 요 내 용 | L5: 비 고
B6: ▶표준내역
B7: 17.목창호공사
B8: [아파트]
B9: WD/평형/실명 | C9: 규격별, 란마/케이싱포함 | F9: EA
B10: WPD/평형/실명 | C10: 규격별, 란마/케이싱포함 | F10: EA
B11: ABS/평형/실명 | C11: 규격별, 란마/케이싱포함 | F11: EA
B12: [산출예시]
B13: WD01/84A/침실1 | C13: 1.000 x 2.100 = 2.100, 란마/케이싱포함, 문선60+185 | F13: M2 | G13: 문선 좌우 폭이 차이날 경우 별도기입
B14: 란마,케이싱/평형/부위 | C14: 규격별 | F14: EA
B15: 창틀,문틀주위사춤 | C15: 우레아폼(WD창호) | F15: M
B22: [PIT,주차장,부대시설]
B23: WD/부속동명/실명 | C23: 규격별, 란마/케이싱포함 | F23: EA
B24: WD/부속동명/실명/슬라이딩도어 | C24: 규격별, 란마/케이싱포함 | F24: EA
B25: WD/부속동명/실명/포켓도어 | C25: 규격별, 란마/케이싱포함 | F25: EA
B26: WPD/부속동명/실명 | C26: 규격별, 란마/케이싱포함 | F26: EA
B27: ABS/부속동명/실명 | C27: 규격별, 란마/케이싱포함 | F27: EA
B28: 란마,케이싱/평형/부위 | C28: 규격별 | F28: EA
B29: 창틀,문틀주위사춤 | C29: 우레아폼(WD창호) | F29: M
B41: ▶견적지침
B42: WD/WPD/ABS | F42: EA | G42: 규격별, 위치별 구분하여 개소로 산출
G43: 문선 좌우 폭이 차이날 경우 별도기입 (EX. 문선60+185)
G44: 주방발코니 창호의 경우 인테리어도서를 우선으로 하며,
G45: PL창호가 아닐 경우 단열목창호로 산출하며 규격란에 명기
G46: 슬라이딩 및 포켓도어(하드웨어포함) 규격란 명시必
B47: 란마,케이싱/평형/부위 | F47: EA | G47: 주방터닝도어 부위의 란마/케이싱을 개소로 산출
G48: 주방발코니 창호가 단열목창호일 경우에도 별도 산출 | L48: 개정
B49: 창틀,문틀주위사춤 | C49: 우레아폼(WD창호) | F49: M | G49: 창호가 건량벽체에 면해 있을 경우 우레아폼 사춤으로 산출
G51: ※ 산출예시
G60: ① 창호사춤 : W＋(H*2) (m)
G61: ② 하드웨어 : 레버핸들1EA, 경첩3EA, 도어스톱, 손끼임방지1EA | L61: 개정
G62: ※ 창호도 상 욕실창호 부호가 PD로 표현되어 있을 경우가 있으나,
G63: PL창호로 산출하지 않도록 주의
G64: ※ PD로 표기시 창호부호도 대로 산출하되, 내역작업시 WPD로 반영

Sheet 16.도배
C2: 구분 | D2: 건축공사 | E2: 공종명 | G2: 16. 도배공사 | H2: 개정 번호 | I2: REV.03 | J2: 제정일 | K2: =+개정내역!$O$4 -> 42697
J3: 개정일 | K3: =+개정내역!$N$4 -> 44748
B5: 품 명 | C5: 규 격 | F5: 단위 | G5: 주 요 내 용 | L5: 비 고
B6: ▶표준내역
B7: [아파트]
B8: 벽지붙이기(석고면) | C8: 평형별(부직포포함) | F8: M2
B9: 벽지붙이기(콘크리트면) | C9: 평형별(부직포포함) | F9: M2
B10: 천정지붙이기 | C10: 평형별 | F10: M2
B11: 옹벽모서리PVC비드 | F11: M
B12: 도배면퍼티작업 | C12: W=150 | F12: 세대
B14: [물량산출]
B15: 벽지붙이기(석고면) | C15: 78A/거실,[개나리]87347-2 | F15: M2
B16: 벽지붙이기(콘크리트면) | C16: 78A/거실,[개나리]87347-2 | F16: M2
B18: [PIT,주차장,부대시설]
B19: 벽지붙이기(콘크리트면) | C19: 부속동(부직포포함) | F19: M2
B20: 벽지붙이기(석고면) | C20: 부속동(부직포포함) | F20: M2
B21: 천정지붙이기 | C21: 부속동 | F21: M2
B22: 옹벽모서리PVC비드 | F22: M
B23: 도배면퍼티작업 | C23: W=150 | F23: 식
B25: ▶견적지침
B26: 벽지붙이기 | F26: M2 | G26: 석고면, 콘크리트면 구분
G27: 천정고로 산출(걸레받이 높이 공제)
G28: 가구후면 미산출(여장 100mm산출)
G29: 냉장고장 상부 수납장 후면 미산출
B30: 천정지붙이기 | F30: M2 | G30: 가구상부 미산출(여장 100mm산출)
B31: 옹벽모서리PVC비드 | F31: M | G31: 옹벽면 아웃코너부위 산출 / 천정고로 산출(걸레받이 공제)
B32: 도배면퍼티작업 | F32: 세대/식 | G32: 아파트 - 전체세대 산출 / 부속동 - 전체 1식 산출

Sheet 17.마루
C2: 구분 | D2: 건축공사 | E2: 공종명 | G2: 17. 마루 및 수장공사 | H2: 개정 번호 | I2: REV.03 | J2: 제정일 | K2: =+개정내역!$O$4 -> 42697
J3: 개정일 | K3: =+개정내역!$N$4 -> 44748
B5: 품 명 | C5: 규 격 | F5: 단위 | G5: 주 요 내 용 | L5: 비 고
B6: ▶표준내역
B7: [아파트]
B8: 강마루깔기 | C8: 평형별/제품별 | F8: M2
B9: 강마루보양 | C9: 자재포함 | F9: M2
B10: 하자보수물량 | C10: 0.01 | F10: M2
B12: [물량산출]
B13: 강마루깔기 | C13: 61A/거실,[스타강마루]KH-713 그레이오크 | F13: M2 | G13: 평형별/부위별,제품사양별
B15: [PIT,주차장,부대시설]
B16: 강마루깔기 | C16: 부속동 | F16: M2
B17: 강마루보양 | C17: 자재포함 | F17: M2
B18: 하자보수물량 | C18: 0.01 | F18: M2
B20: ▶견적지침
B21: 강마루깔기 | F21: M2 | G21: 마루판으로 시공되는 면적을 평형별로 산출
G22: 고정식 가구하부 미산출 (여장 100mm산출)
G23: ※고정식가구 : 주방가구, 붙박이장, 화장대, 키큰장 등
G24: ※아일랜드장 하부산출기준
G25: - 별도 분리된 경우 : 마루 산출
G26: - 별도 분리되었으나 다른장과 연결된 경우 : 마루 미산출
B27: 강마루보양 | F27: M2 | G27: 강마루깔기 물량과 동일물량
B28: 하자보수물량 | F28: M2 | G28: 강마루깔기 1%적용

Sheet 18.도장
C2: 구분 | D2: 건축공사 | E2: 공종명 | G2: 18. 도장공사 | H2: 개정 번호 | I2: REV.03 | J2: 제정일 | K2: =+개정내역!$O$4 -> 42697
J3: 개정일 | K3: =+개정내역!$N$4 -> 44748
B5: 품 명 | C5: 규 격 | F5: 단위 | G5: 주 요 내 용 | L5: 비 고
B6: ▶표준내역
B7: [아파트]
B8: 수성페인트(발코니) | C8: 내벽3회 | F8: M2
B9: 수성페인트(발코니) | C9: 내벽3회,GB면 | F9: M2
B10: 수성페인트(발코니) | C10: 내천정3회 | F10: M2
B11: 수성페인트(발코니) | C11: 내천정3회,GB면 | F11: M2
B12: 수성페인트 | C12: 외벽3회 | F12: M2
B13: 수성페인트 | C13: 외천정3회 | F13: M2
B14: 비닐페인트 | C14: 내천정,GB면 | F14: M2
B15: 저층부몰딩 | C15: 규격별/재질별 | F15: M | L15: 개정
B16: 세라민페인트 | C16: 걸레받이 | F16: M2
B17: 세라민페인트 | C17: 걸레받이,GB면 | F17: M2
B18: 무늬코트 | C18: 내벽/ELEV홀,계단실 | F18: M2
B19: 무늬코트 | C19: 내천정/ELEV홀,계단실 | F19: M2
B20: 무늬코트 | C20: 내천정GB면/ELEV홀 | F20: M2
B21: 석재뿜칠 | C21: 외벽,피로티 | F21: M2
B22: 석재뿜칠 | C22: 외벽,저층부 | F22: M2
B23: 조합페인트 | C23: 철재면 | F23: M2
B24: 에폭시코팅 | C24: 바닥 | F24: M2
B25: 층간죠인트퍼티 | F25: M
B28: [PIT,주차장,부대시설]
B29: 수성페인트 | C29: 내벽3회 | F29: M2
B30: 수성페인트 | C30: 내벽3회,GB면 | F30: M2
B31: 수성페인트 | C31: 내천정3회 | F31: M2
B32: 수성페인트 | C32: 내천정벽3회,GB면 | F32: M2
B33: 수성페인트 | C33: 외벽3회 | F33: M2
B34: 수성페인트 | C34: 외천정3회 | F34: M2
B35: 세라민페인트 | C35: 걸레받이 | F35: M2
B36: 세라민페인트 | C36: 걸레받이,GB면 | F36: M2
B37: 무늬코트 | C37: 내벽/ELEV홀,계단실 | F37: M2
B38: 무늬코트 | C38: 내천정/ELEV홀,계단실 | F38: M2
B39: 석재뿜칠 | C39: 외벽 | F39: M2
B40: 지정뿜칠 | C40: 주차장천정 | F40: M2
... B42: 안전페인트(주차장기둥) | C42: H1200 | F42: M2
B43: 안전페인트(콘크리트연석) | F43: M2
B44: 에폭시라이닝 | C44: 통로구간/1.0T | F44: M2
B45: 에폭시코팅 | C45: 주차구간/0.3T | F45: M2
...

Sheet 19.지붕
C2: 구분 | D2: 건축공사 | E2: 공종명 | G2: 19. 지붕공사 | H2: 개정 번호 | I2: REV.03 | J2: 제정일 | K2: =+개정내역!$O$4 -> 42697
J3: 개정일 | K3: =+개정내역!$N$4 -> 44748
B5: 품 명 | C5: 규 격 | F5: 단위 | G5: 주 요 내 용 | L5: 비 고
B6: ▶표준내역
B7: [PIT,주차장,부대시설]
B8: 지정지붕마감 | C8: 규격별,위치별/후레싱 및 하지틀포함 | F8: M2
B9: 지붕철골트러스 | F9: M2
B14: ▶견적지침
B15: 지정지붕마감 | F15: M2 | G15: 지붕마감 도면 명기시 해당마감으로 산출
G16: 도면에 별도의 명기가 없을시 금속기와(1.2T) 적용
G17: 후레싱 및 하지틀 단가 포함

Sheet 20.코킹
C2: 구분 | D2: 건축공사 | E2: 공종명 | G2: 20. 코킹공사 | H2: 개정 번호 | I2: REV.03 | J2: 제정일 | K2: =+개정내역!$O$4 -> 42697
J3: 개정일 | K3: =+개정내역!$N$4 -> 44748
B5: 품 명 | C5: 규 격 | F5: 단위 | G5: 주 요 내 용 | L5: 비 고
B6: ▶표준내역
B7: [아파트]
B8: 수밀코킹 | C8: 욕실모서리 | F8: M
B9: 수밀코킹 | C9: 세면기 | F9: M
B10: 수밀코킹 | C10: 젠다이 | F10: M
B11: 수밀코킹 | C11: 욕조 | F11: M
B12: 수밀코킹 | C12: 욕실문주위 | F12: M
B13: 수밀코킹 | C13: 샤워부스 | F13: M
B14: 실리콘코킹(3*3) | C14: 현관디딤판+가구면 | F14: M
B15: 실리콘코킹(5*5) | C15: 현관디딤판하부 | F15: M
B16: 실리콘코킹(5*5) | C16: 현관굽도리하부 | F16: M
B17: ELEV 주위코킹 | C17: 10*10 | F17: M
B18: ELEV홀 천정코킹 | C18: 10*10 | F18: M
B19: 창호코킹(STL창호) | C19: 10*10 | F19: M
B20: PD COVER 주위코킹 | C20: 10*10 | F20: M
B21: 죠인트코킹 | C21: 확장대상발코니,크랙유도줄눈 | F21: M | G21: 현장 미시공항목으로 항목삭제 | L21: 개정
B22: 죠인트코킹 | C22: 단위세대,조적+옹벽(발코니) | F22: M
B23: 죠인트코킹 | C23: 공용부,조적+옹벽 | F23: M
B26: [PIT,주차장,부대시설]
B27: 수밀코킹 | C27: 욕실모서리 | F27: M
B28: 수밀코킹 | C28: 세면기 | F28: M
B29: 수밀코킹 | C29: 젠다이 | F29: M
B30: 수밀코킹 | C30: 욕조 | F30: M
B31: 수밀코킹 | C31: 욕실문주위 | F31: M
B32: ELEV 주위코킹 | C32: 10*10 | F32: M
B33: 죠인트코킹 | C33: 블럭면 | F33: M
B34: 창호코킹(STL창호) | C34: 10*10 | F34: M
B35: PD COVER 주위코킹 | C35: 10*10 | F35: M
B41: ▶견적지침
B42: 수밀코킹 | F42: M | G42: "세대내 코킹 산출부위" 표 참조
B43: ELEV 주위코킹 | F43: M | G43: E/V홀 내측면 후레임 주위 3면 산출(하부제외)
B44: ELEV홀 천정코킹 | F44: M | G44: 기준층 EV홀 천정주위 마감변경으로 코킹산출부위 추가 | L44: 개정
B45: 창호코킹(STL창호) | F45: M | G45: AL, PL창호를 제외한 모든창호 3면 산출(하부제외)
G46: : AL, PL창호 코킹은 각 공종 내역에 별도편성
B47: PD COVER 주위코킹 | F47: M | G47: EV홀 건식PD 주위 상부, 측면구간 산출(높이 천정고)
B48: 죠인트코킹 | C48: 단위세대,조적+옹벽(발코니) | F48: M | G48: 단위세대 조적+옹벽부위 수직/수평 길이산출
B49: 죠인트코킹 | C49: 조적/블록면+옹벽 | F49: M | G49: 조적 및 블록이 옹벽과 만나는 부위 상부, 측면구간 산출
...

Sheet 21.사인물
C2: 구분 | D2: 건축공사 | E2: 공종명 | G2: 21. 사인물공사 | H2: 개정 번호 | I2: REV.03 | J2: 제정일 | K2: =+개정내역!$O$4 -> 42697
J3: 개정일 | K3: =+개정내역!$N$4 -> 44748
B5: 품 명 | C5: 규 격 | F5: 단위 | G5: 주 요 내 용 | L5: 비 고
B6: ▶표준내역
B7: [옥외]
B8: 주출입구문주사인 | C8: 단지명/B.I/C.I/등박스/행복의문/도로명주소 | F8: SET
B9: 부출입구문주사인 | C9: 단지명/B.I/C.I/등박스/행복의문/도로명주소 | F9: SET
B10: 측벽CI로고사인-조명형 | C10: 3870*4000/LED스텐채널 | F10: EA
B11: 측벽CI로고사인-비조명형 | C11: 3870*4000/스텐채널 | F11: EA
B12: 측벽BI로고사인-조명형 | C12: 3120*6000/LED스텐채널 | F12: EA
B13: 측벽BI로고사인-비조명형 | C13: 3120*6000/스텐채널 | F13: EA
B14: 측벽동표시사인-상동수 | C14: H:1100/스텐채널 | F14: EA
B15: 측벽동표시사인-하동수 | C15: H:1000/스텐채널 | F15: EA
B16: 지상동출입구사인(피로티) | C16: H:350,240/LED에폭시스텐채널 | F16: EA
B17: 단지유도표지판 | F17: EA
B18: 게시판 | F18: EA
B19: 단지입구표지판 | F19: EA
B20: 단지종합안내판 | F20: EA
B21: 지하주차장표지판 | F21: EA
B22: 단지내시설표지판 | F22: EA
B23: 주차장안내사인 | C23: 700*2000/스텐FRAME | F23: EA
B24: 관리사무소사인 | C24: H:300/LED에폭시스텐채널/FRAME | F24: EA
B25: 도서관사인 | C25: H:300/LED에폭시스텐채널/FRAME | F25: EA
B26: 경로당사인 | C26: H:300/LED에폭시스텐채널/FRAME | F26: EA
B27: 휘트니스센터사인 | C27: H:300/LED에폭시스텐채널/FRAME | F27: EA
B28: 보육시설사인 | C28: H:300/LED에폭시스텐채널/FRAME | F28: EA
B29: 경비실사인 | C29: H:250/스텐HL입체문자 | F29: EA
B30: 머릿돌 | F30: EA
B33: [옥내]
B34: 세대표시사인 | C34: 150*60/신주+아크릴 | F34: EA
B35: EV홀층표시사인 | C35: H:150/20T아크릴스카시 | F35: EA
B36: 계단실층표시사인 | C36: H:150/20T아크릴스카시 | F36: EA
B37: 공용부실명패사인 | C37: 200*80/아크릴 | F37: EA
B38: 일반실명패사인 | C38: 150*65/아크릴 | F38: EA
B39: 화장실실명패사인 | C39: 180*250/아크릴 | F39: EA
B40: 옥내게시판사인 | C40: 1150*700/갈바FRAME | F40: EA
B41: 우편함사인/동명(타입명) | C41: 규격별 | F41: EA
B42: 우편함 | C42: 270*160*170 | F42: EA
B43: 우편함/폐건전지함 | C43: 270*160*170 | F43: EA
B44: 우편함/반송함 | C44: 270*320*170 | F44: EA
...

Sheet 자재납품
A8: - 제 3 장 -
A16: 자재납품(건축)

Sheet 1.AL폼
C2: 구분 | D2: 자재납품 | E2: 공종명 | G2: 1. AL FORM | H2: 개정 번호 | I2: REV.03 | J2: 제정일 | K2: =+개정내역!$O$4 -> 42697
J3: 개정일 | K3: =+개정내역!$N$4 -> 44748
B5: 품 명 | C5: 규 격 | F5: 단위 | G5: 주 요 내 용 | L5: 비 고
B6: ▶표준내역
B7: AL FORM | C7: 알폼수직 | F7: M2 | G7: 옹벽, 인방보
B8: AL FORM | C8: 알폼슬라브 | F8: M2 | G8: 슬라브
B9: AL FORM | C9: 알폼계단 | F9: M2 | G9: 계단
B10: 동바리 | F10: M2 | G10: 알폼 수량 총 합계
B11: 부속철물 | F11: M2 | G11: 알폼 수량 총 합계
B12: TIE | C12: 내,외부 | F12: M2 | G12: 알폼 수량 총 합계
B13: 저소음시스템 | F13: M2 | G13: 알폼 수량 총 합계 (도심지공사 산출) | L13: 개정

Sheet 2.갱폼
C2: 구분 | D2: 자재납품 | E2: 공종명 | G2: 2. GANG FORM | H2: 개정 번호 | I2: REV.03 | J2: 제정일 | K2: =+개정내역!$O$4 -> 42697
J3: 개정일 | K3: =+개정내역!$N$4 -> 44748
B5: 품 명 | C5: 규 격 | F5: 단위 | G5: 주 요 내 용 | L5: 비 고
B6: ▶표준내역
B7: GANG FORM | C7: 갱폼높이 | F7: M2 | G7: 여유높이 포함 | M7: 외벽둘레*최상층H+0.2
B8: GANG FORM | C8: 갱폼높이, 층변화(3개층 이상) | F8: M2 | G8: 여유높이 포함 | M8: 외벽둘레*최상층H+0.2
B9: 작업발판 | C9: EX-Metal | F9: M | G9: 기본 : 4단 | M9: 외벽둘레*4단(층변화 갱폼시 층변화 면적도 포함)
B10: 작업발판 | C10: 유공발판 | F10: M | G10: 기본 : 1단 | M10: 외벽둘레*1단(층변화 갱폼시 층변화 면적도 포함)
B11: 자재보관함(공구함) | C11: 500*500*2000 | F11: EA | G11: 동당 2개소 | M11: 동당2개소
B12: 사다리 | F12: EA | G12: 기본 : 세대당 3EA | M12: 세대당3개소
B13: 토보드 | C13: H=100 | F13: M | G13: 기본 : 1단 | M13: 외벽둘레*1단(층변화 갱폼시 층변화 면적도 포함)
B14: 핸드레일 | C14: ㅁ-20*40 | F14: M | G14: 기본 : 12단 | M14: 외벽둘레*12단(층변화 갱폼시 층변화 면적도 포함)
B15: 줄눈시공 | F15: M | M15: 외벽둘레*5단(층변화 갱폼시 층변화 면적도 포함)
B16: 추락방지 브라켓 | F16: EA
B17: 추락방지 인양시스템 | F17: EA
B18: 층고변화 수정비 | F18: 동 | M18: 동개소
B19: 층변화 수정비 | F19: 개소 | M19: 층변화 개소(층변화 갱폼포함 층변화 구간)
B20: 파라펫 수정비 | F20: 동 | M20: 동개소
B21: 옥탑 수정비 | F21: 개소 | M21: 코어개소
B22: 호이스트/압송관 수정비 | F22: 동 | M22: 코어개소
B23: G/F BUY-BACK | F23: 식 | M23: ?
M29: 추락방지브라켓 (외벽둘레+층변화길이)*41.67%
M30: 추락방지인양시스템 (외벽둘레+층변화길이)*41.67%

Sheet 3.배수판
C2: 구분 | D2: 자재납품 | E2: 공종명 | G2: 3.배수판공사 | H2: 개정 번호 | I2: REV.03 | J2: 제정일 | K2: =+개정내역!$O$4 -> 42697
J3: 개정일 | K3: =+개정내역!$N$4 -> 44748
B5: 품 명 | C5: 규 격 | F5: 단위 | G5: 주 요 내 용 | L5: 비 고
B6: ▶표준내역
B7: PVC배수판설치 | C7: 바닥, 45T, 통로구간 고정핀포함 | F7: M2
B8: PVC배수판설치 | C8: 벽, 70T, 슬리브포함, 도장포함 | F8: M2
B12: ▶견적지침
B13: 바닥배수판 | F13: M2 | G13: 최하층 주차장 바닥면적 산출
G14: 통로구간 들뜸 방지를 위한 고정핀 단가포함
B15: 벽체배수판 | F15: M2 | G15: 흙과 접하는 부위의 슬라브 하부높이까지 산출
G16: 벽체디자인을 위한 도장 단가포함

Sheet 4.주방가구
C2: 구분 | D2: 자재납품 | E2: 공종명 | G2: 4.주방가구공사 | H2: 개정 번호 | I2: REV.03 | J2: 제정일 | K2: =+개정내역!$O$4 -> 42697
J3: 개정일 | K3: =+개정내역!$N$4 -> 44748
B5: 품 명 | C5: 규 격 | F5: 단위 | G5: 주 요 내 용 | L5: 비 고
B6: ▶표준내역
B7: [기본공사]
B8: 주방가구(부속동명) | C8: L(길이)*W(폭) | F8: SET
B12: [확장공사]
B13: 주방가구(하부장)/평형별 | C13: L(길이)*W(폭)*H(높이) | F13: SET
B14: 주방가구(상부장)/평형별 | C14: L(길이)*W(폭)*H(높이) | F14: SET
B15: 주방가구(상부오픈장)/평형별 | C15: L(길이)*W(폭)*H(높이) | F15: SET
B16: 주방가구(냉장고장)/평형별 | C16: L(길이)*W(폭)*H(높이) | F16: SET
B17: 주방가구(아일랜드장)/평형별 | C17: L(길이)*W(폭)*H(높이) | F17: SET
B18: 주방가구(장식장)/평형별 | C18: L(길이)*W(폭)*H(높이) | F18: SET
B19: FIX판넬/부위별 | C19: L(길이)*W(폭)*H(높이) | F19: SET
B20: 주방펜트리도어/평형별 | C20: L(길이)*H(높이) | F20: SET
B26: ▶견적지침
B27: ※공통사항 | G27: 인테리어도면 참고하여 기본 및 확장가구 구분산출
G28: 꺾인(ㄴ,ㄷ) 구간 중복부위 없이 산출
G29: 문짝재질이 가구재질과 상이할 경우, 규격란 기재
G30: 옵션 선택항목 품명란 별도 표기(무상옵션)
G31: FIX판넬은 규격란에 포함사항 기재없이, 별도로 산출 | L31: 개정
G32: FIX판넬 이외의 포함사항 있을 경우, 규격란 기재
G33: ※"ㄷ"자 하부장 산출기준
G34: 하부장 : A+B
G35: 아일랜드장 : C

Sheet 5.일반가구
C2: 구분 | D2: 자재납품 | E2: 공종명 | G2: 5.일반가구공사 | H2: 개정 번호 | I2: REV.03 | J2: 제정일 | K2: =+개정내역!$O$4 -> 42697
J3: 개정일 | K3: =+개정내역!$N$4 -> 44748
B5: 품 명 | C5: 규 격 | F5: 단위 | G5: 주 요 내 용 | L5: 비 고
B6: ▶표준내역
B7: [기본공사]
B8: 현관신발장/평형별 | C8: L(길이)*W(폭)*H(높이) | F8: SET
B9: 현관전신거울/평형별 | C9: L(길이)*H(높이), 은경형태별 | F9: SET
B10: 현관신발장/부속동 | C10: L(길이)*W(폭)*H(높이) | F10: SET
B11: 붙박이장/부속동/실명 | C11: L(길이)*W(폭)*H(높이) | F11: SET
B12: 락카 | C12: L(길이)*W(폭), 주민공동시설 | F12: EA
B15: [확장공사]
B16: 현관신발장/평형별 | C16: L(길이)*W(폭)*H(높이) | F16: SET
B17: 침실붙박이장/평형별 | C17: L(길이)*W(폭)*H(높이) | F17: SET
B18: 침실붙박이장/평형별 | C18: L(길이)*W(폭)*H(높이) | F18: SET
B19: 복도장식장/평형별 | C19: L(길이)*W(폭)*H(높이) | F19: SET
B20: 화장대/평형별 | C20: L(길이)*W(폭)*H(높이) | F20: SET
B21: 현관팬트리도어/평형별 | C21: L(길이)*H(높이) | F21: SET
B22: 복도팬트리도어/평형별 | C22: L(길이)*H(높이) | F22: SET
B23: 드레스룸도어/평형별 | C23: L(길이)*H(높이) | F23: SET
B24: 안방붙박이장/평형별 | C24: L(길이)*W(폭)*H(높이) | F24: SET
B25: FIX판넬/부위별 | C25: L(길이)*W(폭)*H(높이) | F25: SET
B26: 현관중문(타입별)/평형별 | C26: L(길이)*H(높이)/유리,레일포함 | F26: 개소 | G26: 무상옵션 경우
B30: ▶견적지침
B31: ※공통사항 | G31: 인테리어도면 참고하여 기본 및 확장가구 구분산출
G32: 현관중문 산출시, 1슬라이딩/3연동/스윙 등 타입별 구분산출
G33: 문짝재질이 가구재질과 상이할 경우, 규격란 기재
G34: 옵션 선택항목 품명란 별도 표기(무상옵션)
G35: FIX판넬은 규격란에 포함사항 기재없이, 별도로 산출 | L35: 개정
G36: FIX판넬 이외의 포함사항 있을 경우, 규격란 기재

Sheet 6.시스템가구
C2: 구분 | D2: 자재납품 | E2: 공종명 | G2: 6.시스템가구공사 | H2: 개정 번호 | I2: REV.03 | J2: 제정일 | K2: =+개정내역!$O$4 -> 42697
J3: 개정일 | K3: =+개정내역!$N$4 -> 44748
B5: 품 명 | C5: 규 격 | F5: 단위 | G5: 주 요 내 용 | L5: 비 고
B6: ▶표준내역
B7: [기본공사]
B8: 시스템가구/발코니세탁실/평형별 | C8: L(길이)*W(폭)*H(높이), 타입별 | F8: SET
B9: 시스템가구/복도팬트리/평형별 | C9: L(길이)*W(폭)*H(높이) | F9: SET
B10: 시스템가구/대피공간/평형별 | C10: L(길이)*W(폭)*H(높이), O단선반 | F10: SET
B14: [확장공사]
B15: 시스템가구/드레스룸/평형별 | C15: L(길이)*W(폭)*H(높이), O단서랍장포함 | F15: SET
B16: 시스템가구/현관창고/평형별 | C16: L(길이)*W(폭)*H(높이) | F16: SET
B17: 시스템가구/주방팬트리/평형별 | C17: L(길이)*W(폭)*H(높이) | F17: SET
B21: ▶견적지침
B22: ※공통사항 | G22: 인테리어도면 참고하여 기본 및 확장가구 구분산출
G23: 꺾인(ㄴ,ㄷ) 구간 중복부위 없이 산출
G24: 발코니세탁실선반 산출시, 2단선반/접이식 등 타입별 산출
G25: 기타 포함사항 있을 경우, 규격란 기재

Sheet 7.인조석상판
C2: 구분 | D2: 자재납품 | E2: 공종명 | G2: 7.인조석공사 | H2: 개정 번호 | I2: REV.03 | J2: 제정일 | K2: =+개정내역!$O$4 -> 42697
J3: 개정일 | K3: =+개정내역!$N$4 -> 44748
B5: 품 명 | C5: 규 격 | F5: 단위 | G5: 주 요 내 용 | L5: 비 고
B6: ▶표준내역
B7: [주방상판]
B8: [아파트]
B9: 주방가구상판/평형별/타공포함 | C9: W(폭)*두께, 제품별 | F9: M
B10: 주방가구상판/평형별 | C10: W(폭)*두께, 제품별 | F10: M
B11: 주방가구 상판(장식장)/평형별 | C11: W(폭)*두께, 제품별 | F11: M
B12: 주방가구 상판(아일랜드)/평형별 | C12: W(폭)*두께, 제품별 | F12: M
B13: 주방가구 뒷선반/평형별 | C13: W(폭)*두께, 제품별 | F13: M
B14: 주방가구 뒷턱/평형별 | C14: H(높이)*두께, 제품별 | F14: M
B15: 주방가구 벽체/평형별 | C15: 두께, 제품별 | F15: M2 | G15: E-스톤 적용시
B17: [부속동]
B18: 주방가구 상판/부속동 실명/타공포함 | C18: W(폭)*두께, 제품별 | F18: M
B22: [재료분리대]
B23: [아파트]
B24: 인조대리석재료분리대/평형별(자재) | C24: 실별, L(길이)*W(폭)*H(높이), 등급별 | F24: M
B25: 인조대리석샤워부스씰/평형별(시공) | C25: 실별, L(길이)*W(폭)*H(높이), 등급별 | F25: M
B27: [부속동]
B28: 인조대리석문틀씰 | C28: 부속동 | F28: M
B31: [현관디딤판 등]
B32: [아파트]
B33: 현관디딤판/평형별 | C33: L(길이)*W(폭)*두께별, 제품별 | F33: EA
B34: 현관창고디딤판/평형별 | C34: L(길이)*W(폭)*두께별, 제품별 | F34: EA
B35: 현관굽도리/평형별 | C35: H(높이)*두께별, 제품별 | F35: M
B36: 현관걸레받이/평형별 | C36: H(높이)*두께별, 제품별 | F36: M
B37: 욕실선반(공용욕실)/평형별 | C37: L(길이)*W(폭)*두께별, 제품별 | F37: EA
B38: 욕실선반(부부욕실)/평형별 | C38: L(길이)*W(폭)*두께별, 제품별 | F38: EA
B39: 화장대상판/평형별 | C39: L(길이)*W(폭)*두께별, 제품별 | F39: EA
B40: 화장대뒷벽/평형별 | C40: L(길이)*H(높이)*두께별, 제품별 | F40: EA
B41: 신발장상판/평형별 | C41: L(길이)*W(폭)*두께별, 제품별 | F41: EA
B43: [부속동]
B44: 현관디딤판/부속동 | C44: L(길이)*W(폭)*두께별 | F44: EA
B45: 현관굽도리/부속동 | C45: H(높이)*두께별 | F45: M
B46: 현관걸레받이/부속동 | C46: H(높이)*두께별 | F46: M
B47: 욕실선반(부속동) | C47: L(길이)*W(폭)*두께별 | F47: EA
B51: ▶견적지침
B52: [주방가구 상판]
B53: ※공통사항 | G53: 인테리어도면 참고하여 제품별/등급별 구분산출
...

Sheet 8.욕실자재
C2: 구분 | D2: 자재납품 | E2: 공종명 | G2: 8. 욕실자재공사 (욕조,욕실장, 샤워부스) | H2: 개정 번호 | I2: REV.03 | J2: 제정일 | K2: =+개정내역!$O$4 -> 42697
J3: 개정일 | K3: =+개정내역!$N$4 -> 44748
B5: 품 명 | C5: 규 격 | F5: 단위 | G5: 주 요 내 용 | L5: 비 고
B6: ▶표준내역
B7: [욕조]
B8: 욕조(세라믹) | C8: 평형별/위치별/크기별 | F8: SET
B9: 욕조(아크릴) | C9: 평형별/위치별/크기별 | F9: SET
B10: 욕조(하이그로시) | C10: 평형별/위치별/크기별 | F10: SET
B11: [산출예시]
B12: 욕조(세라믹) | C12: 84A/공용/L1600*W800*H400 | F12: SET
B14: [욕실장]
B15: 욕실장 | C15: 평형별/위치별/크기별/개폐방식 | F15: SET
B16: [산출예시]
B17: 욕실장 | C17: 84A/공용/L1490*W150*H830/슬라이드 | F17: SET
B20: [샤워부스] | C20: 접합유리여부 확인
B21: 샤워부스 | C21: 평형별/위치별/크기별/유리재질별 | F21: SET
B22: [산출예시]
B23: 샤워부스 | C23: 84A/부부/L1100*H2000/접합유리 | F23: SET
B27: ▶견적지침
B28: 욕조 | F28: SET | G28: 도면표기에 따라 세라믹/아크릴/하이그로시 재질별 산출
G29: 폭(W)에 따라 단가 결정(길이 무관)
B30: 욕실장 | F30: SET | G30: 도면표기에 따라 슬라이드/여닫이 개폐방식별 산출
G31: 콘센트박스, 드라이거치대, 댐핑시스템 구성시 별도단가 추가반영
B32: 샤워부스 | F32: SET | G32: 도면표기에 따라 강화유리/접합유리 유리재질별 산출
G33: 샤워부스 주위 코킹 포함

Sheet 9.욕실천정재
C2: 구분 | D2: 자재납품 | E2: 공종명 | G2: 9.욕실천정재공사 | H2: 개정 번호 | I2: REV.03 | J2: 제정일 | K2: =+개정내역!$O$4 -> 42697
J3: 개정일 | K3: =+개정내역!$N$4 -> 44748
B5: 품 명 | C5: 규 격 | F5: 단위 | G5: 주 요 내 용 | L5: 비 고
B6: ▶표준내역
B7: SMC천정재설치/평형별 | C7: 천정틀/몰딩/점검구/코킹포함 | F7: M2
B8: ABS천정재설치/평형별 | C8: 천정틀/몰딩/점검구/코킹포함 | F8: M2
B15: ▶견적지침
B16: 욕실천정재설치 | F16: M2 | G16: 인테리어도면(마감재리스트)표기에 따라 SMC/ABS 재질별 산출
G17: 천정틀 및 몰딩, 점검구, 코킹 포함항목

Sheet 10.하드웨어
C2: 구분 | D2: 자재납품 | E2: 공종명 | G2: 10.하드웨어공사 | H2: 개정 번호 | I2: REV.03 | J2: 제정일 | K2: =+개정내역!$O$4 -> 42697
J3: 개정일 | K3: =+개정내역!$N$4 -> 44748
B5: 품 명 | C5: 규 격 | F5: 단위 | G5: 주 요 내 용 | L5: 비 고
B6: ▶표준내역
B7: 10.하드웨어공사
B8: [강재창호]
B9: 도아록 | C9: 대피공간/세대 | F9: EA
B10: 도아록 | C10: 실외기실/세대 | F10: EA
B11: 도아록 | C11: FSD(SD)/공용 | F11: EA
B12: 도아록 | C12: FSD(SD)/부속동 | F12: EA
B13: 도아록 | C13: FSD(SD)공정/부속동 | F13: EA
B14: 도아체크 | C14: 현관/단위세대 | F14: EA
B15: 도아체크 | C15: 대피공간/단위세대 | F15: EA
B16: 도아체크 | C16: 자동폐쇄장치/계단실 | F16: EA
B17: 도아체크 | C17: 자동폐쇄장치/ELEV.홀 | F17: EA
B18: 도아체크 | C18: 파워형/옥탑,지붕 | F18: EA
B19: 도아체크 | C19: 방화용(일반용)/공용 | F19: EA
B20: 도아체크 | C20: 방화용(일반용)/부속동 | F20: EA
... B25: 우선순위조절기 | C25: FSD(SD)/양개도어/부속동 | F25: EA
B26: 비상문자동폐쇄장치 | C26: 지붕층 | F26: EA | G26: 금속공사에서 이관 | L26: 개정
B29: [목재창호]
B30: 레버핸들 | C30: 평형별/안방,잠금장치포함 | F30: EA
B31: 레버핸들 | C31: 평형별/실명 | F31: EA
B32: 도아록 | C32: 목재문/부속동 | F32: EA
B33: 정첩 | C33: 니켈탈착식 | F33: EA
B34: 도아스톱 | C34: BUMP ON, 침실 | F34: EA
B35: 도아스톱 | C35: 일자형 | F35: EA
B36: 손끼임방지장치 | F36: EA | G36: 목창호공사에서 이관 | L36: 개정
B38: [AL창호]
B39: 자동개폐장치 | C39: AW | F39: EA
B43: ▶견적지침
B44: ※ 부위별 적용사항 | L44: 개정
B68: ※ 세대현관 도어록(디지털도어록) - 전기공사분, 건축 미산출
B69: ※ 주방발코니 손끼임방지재는 목재(단열)도어만 산출, PD터닝도어 미산출
B70: ※ 오피스텔 배연창(AW/PW)의 경우에 한하여 자동개폐장치 산출
B71: ※ AD도어 플로어힌지의 경우, AL창호공사 포함사항이므로 미산출
B72: ※ 도어스톱(말발굽) 미산출
B73: ※ 오토힌지, 마그네틱릴리즈는 상시개방형(매립형) 방화문 표기시 산출하며, 해당부위의 자동개폐장치 미산출
B74: ※ 하드웨어 별도 할증없음

Sheet 11.발코니난간대
C2: 구분 | D2: 자재납품 | E2: 공종명 | G2: 11.발코니난간대공사 | H2: 개정 번호 | I2: REV.03 | J2: 제정일 | K2: =+개정내역!$O$4 -> 42697
J3: 개정일 | K3: =+개정내역!$N$4 -> 44748
B5: 품 명 | C5: 규 격 | F5: 단위 | G5: 주 요 내 용 | L5: 비 고
B6: ▶표준내역
B7: 발코니난간대/평형별 | C7: 높이별 | F7: M
B8: 주계단핸드레일 | C8: 높이별 | F8: M
B9: 계단참안전난간 | C9: 최상층 (H=1200) | F9: M
B10: 주계단안전난간 | C10: 높이별 | F10: M
B11: ELEV홀안전난간 | C11: 높이별 | F11: M
B14: ▶견적지침
B15: ※공통사항 | G15: 난간대높이 산정시, 아래 2가지 규정들을 근거로 하여
G16: 도면표기 높이가 해당 규정에 미달될 경우, 규정에 부합되는 높이로
G17: 수정하여 산출
G18: - 주계단핸드레일 : 높이 900mm이상
G19: - 그 외 난간대 : 높이 1,200mm이상
B20: 발코니난간대/평형별 | F20: M | G20: 세대 거실 및 침실 등 확장발코니 부위 난간대
B21: 주계단핸드레일 | F21: M | G21: 아파트 계단실 지하층 ~ 최상층 산출
B22: 계단참안전난간 | F22: M | G22: 아파트 계단실 최상층 계단참 오픈부위 산출 (높이 1,200)
B23: 주계단안전난간 | F23: M | G23: 계단실 CAW(커튼월)창호 부위 산출
B24: ELEV홀안전난간 | F24: M | G24: EV홀 CAW(커튼월)창호 부위 산출
B27: ※주택건설기준 등에 관한 규정
B28: 제 18조 2항 | C28: 난간의 각 부위의 치수는 다음 각호의 기준에 적합하여야 한다.
C29: 1. 난간의 높이 : 바닥의 마감면으로부터 120센티미터 이상. 다만, 건축물내부 계단에 설치하는 난간, 계단중간에
C30: 설치하는 난간 기타 이와 유사한 것으로 위험이 적은 장소에 설치하는 난간의 경우에는 90센티미터
C31: 이상으로 할 수 있다.
B33: ※발코니 등의 구조변경절차 및 설치기준
B34: 제 5조 1항 | C34: 발코니를 거실등으로 사용하는 경우 난간의 높이는 1.2미터 이상이어야 하며 난간에 난간살이 있는 경우에는
C35: 난간살 사이의 간격을 10센티미터 이하의 간격으로 설치하는 등 안전에 필요한 조치를 하여야 한다.

Sheet 12.방화문
C2: 구분 | D2: 자재납품 | E2: 공종명 | G2: 12.방화문공사 | H2: 개정 번호 | I2: REV.03 | J2: 제정일 | K2: =+개정내역!$O$4 -> 42697
J3: 개정일 | K3: =+개정내역!$N$4 -> 44748
B5: 품 명 | C5: 규 격 | F5: 단위 | G5: 주 요 내 용 | L5: 비 고
B6: ▶표준내역
B7: 12.방화문공사
B8: [단위세대]
B9: FSD/현관 | C9: 규격별 | F9: EA
B10: FSD/대피공간 | C10: 규격별 | F10: EA
B11: FSD/대피공간 | C11: 규격별/일면시트 | F11: EA
B12: FSD(SD)/실외기실 | C12: 규격별 | F12: EA
B13: 하드웨어달기 | C13: 도아록,도아스톱,도아체크 | F13: SET
B14: 방화시험성적비용 | C14: 납품자재 시험실시 | F14: 식
B16: [공용부 및 부속동]
B17: FSD/부위 | C17: 규격별 | F17: EA
B18: SD/부위 | C18: 규격별 | F18: EA
B19: 하드웨어달기 | C19: FSD,SD/자재별도 | F19: 조
B41: ▶견적지침
B42: FSD/현관,대피공간 | F42: EA
B43: FSD(SD)/실외기실 | F43: EA | G43: 일면시트가 반영되는 경우 별도항목 구분 및 명기
B44: FSD(SD)/공용 | F44: EA | G44: 공용부 상시개방형(매립형) 방화문의 경우 별도항목으로 산출 | L44: 개정
B45: FSD(SD)/부속동 | F45: EA
G46: 세대 및 공용부/부속동 방화문은 산출 | L46: 개정
G47: (금속공사에서 이관, 점검구 방화문 제외)
B48: 하드웨어달기 | F48: SET | G48: 하드웨어 설치비, FSD/SD 문짝 하나당 1개소 산출(양개문 2개소)
B49: 방화시험성적비용 | F49: 식 | G49: 단위세대 방화문 1식 적용

Sheet 13.층간소음재
C2: 구분 | D2: 자재납품 | E2: 공종명 | G2: 13.층간소음재공사 | H2: 개정 번호 | I2: REV.03 | J2: 제정일 | K2: =+개정내역!$O$4 -> 42697
J3: 개정일 | K3: =+개정내역!$N$4 -> 44748
B5: 품 명 | C5: 규 격 | F5: 단위 | G5: 주 요 내 용 | L5: 비 고
B6: ▶표준내역
B7: [아파트]
B8: 층간바닥재깔기(자재포함)-방통죠인트필러포함 | C8: 두께별, 단열재종류(호수) | F8: M2
B9: 단열재바닥깔기(단열재별도) | C9: 두께별, 단열재종류(호수) | F9: M2
B10: 바닥충격음 측정시험 | C10: 전평형 | F10: 회
B14: [PIT,주차장,부대시설]
B15: 단열재바닥깔기(단열재별도) | C15: 두께별, 단열재종류(호수) | F15: M2
B20: ▶견적지침
B21: 층간바닥재깔기(자재포함)-방통죠인트필러포함 | F21: M2 | G21: 기준층 세대 바닥면적 산출, 단열재 포함
B22: 단열재바닥깔기(단열재별도) | F22: M2 | G22: 아파트 : 최하층 세대 바닥면적 산출
G23: 부속동 : 경로방, 보육시설 등 바닥면적 산출
G24: 단열재 별도 (원재료비 산출 - 할증 10%)
B25: 바닥충격음 측정시험 | F25: 회 | G25: 세대 평형별 1회 산출

Sheet 14.강재집수정
C2: 구분 | D2: 자재납품 | E2: 공종명 | G2: 14.강재집수정공사 | H2: 개정 번호 | I2: REV.03 | J2: 제정일 | K2: =+개정내역!$O$4 -> 42697
J3: 개정일 | K3: =+개정내역!$N$4 -> 44748
B5: 품 명 | C5: 규 격 | F5: 단위 | G5: 주 요 내 용 | L5: 비 고
B6: ▶표준내역
B7: 강재집수정(영구배수) | C7: 규격별 | F7: EA | M7: 현장 개소 및 견적 반영
B8: 강재집수정(ELEV) | C8: 규격별 | F8: EA | M8: 현장 개소 및 견적 반영
B9: 강재집수정 | C9: 규격별 | F9: EA | M9: 현장 개소 및 견적 반영
B11: [산출예시]
B12: 강재집수정(ELEV) | C12: 2300*2400*H2050 | F12: EA
B13: 강재집수정 | C13: Φ1,100 * H 1,219 | F13: EA

Sheet 기타견적기준
A8: - 제 3 부 -
A16: 기타 견적기준

Sheet 1.주요부위 산출기준
C2: 구분 | D2: 기타 견적기준 | E2: 공종명 | G2: 1. 주요부위 산출기준 | H2: 개정 번호 | I2: REV.03 | J2: 제정일 | K2: =+개정내역!$O$4 -> 42697
J3: 개정일 | K3: =+개정내역!N4 -> 44748
B5: ▶주요부위 산출기준
B6: [E/V홀]
B7: - 지하층 | F7: 바닥 | G7: 지정석재
F8: 천정 | G8: SMC천정재
F9: 벽 | G9: 폴리싱타일
B11: - 지상1층(주출입구) | F11: 바닥 | G11: 지정석재
F12: 천정 | G12: 석고보드(9.5T+12.5T) + 비닐페인트
F13: 벽 | G13: 폴리싱타일
B15: - 지상층(기준층) | F15: 바닥 | G15: 지정타일
F16: 천정 | G16: 석고보드(9.5T+12.5T) + 무늬코트
F17: 벽 | G17: 수지미장 + 무늬코트/세라민페인트
B19: [계단실] | F19: 바닥 | G19: 지정타일
F20: 천정 | G20: 면처리 + 무늬코트
F21: 벽 | G21: 수지미장 + 무늬코트/세라민페인트
B23: [E/V기계실] | F23: 바닥 | G23: 무근 + 쇠흙손 + 에폭시코팅
F24: 천정 | G24: G/W(그라스울)50MM+G/C(그라스크로스)
F25: 벽 | G25: G/W(그라스울)50MM+G/C(그라스크로스)
B27: [PIT]
B28: - 최하층 | F28: 바닥 | G28: - 배수판 有 : 무근 + 쇠흙손
G29: - 배수판 無 : 액체방수 + 보호몰탈
F30: 천정 | G30: 면처리
F31: 벽 | G31: - 외벽 : 액체방수 + 보호몰탈
G32: - 내벽 : 면처리
B34: - 최하층제외 | F34: 바닥 | G34: 쇠흙손 (도면에 무근Con'c 표기시에도 미적용)
F35: 천정 | G35: 면처리
F36: 벽 | G36: - 외벽(흙 접하는 부위) : 액체방수 + 보호몰탈
G37: - 외벽(흙 접하지 않는 부위)/내벽 : 면처리
B39: [지하주차장]
F40: 바닥 | G40: - 최하층 : 배수판 + 무근 + 쇠흙손마감 + 에폭시코팅/에폭시라이닝
G41: - 최하층제외 : 무근 + 쇠흙손마감 + 에폭시코팅/에폭시라이닝
G42: ※ 최하층 제외한 주차장바닥 무근Con'c 적용여부는 도면표기 기준
F43: 천정 | G43: 지정뿜칠
F44: 벽 | G44: - 외벽(흙 접하는 부위) : 액체방수 + 배수판
G45: - 외벽(흙 접하지 않는 부위)/내벽 : 면처리 + 수성페인트
B47: [경로당/보육시설] | F47: 바닥 | G47: 강마루
F48: 천정 | G48: 석고보드+벽지
F49: 벽 | G49: 석고보드+벽지
B51: [그 외 부속동] | F51: 바닥 | G51: 비닐계타일
...

Sheet 2.부자재환산수량
C2: 구분 | D2: 기타 견적기준 | E2: 공종명 | G2: 2. 부자재 환산수량 | H2: 개정 번호 | I2: REV.03 | J2: 제정일 | K2: =+개정내역!$O$4 -> 42697
J3: 개정일 | K3: =+개정내역!$N$4 -> 44748
B5: ▶부자재 환산수량
N22: =

Sheet 3.자재할증
C2: 구분 | D2: 기타 견적기준 | E2: 공종명 | G2: 3. 자재할증(지급자재) | H2: 개정 번호 | I2: REV.03 | J2: 제정일 | K2: =+개정내역!$O$4 -> 42697
J3: 개정일 | K3: =+개정내역!$N$4 -> 44748
B5: ▶자재할증(지급자재)

Sheet 카메라

Sheet 코킹
A1: 항 목 | B1: 변경전 | C1: 변경후 | D1: 변경사유
A2: 욕실모서리 | B2: ○ | C2: ○
A3: 세면기 | B3: ○ | C3: 상부1면 | D3: 실시공부위 산출
A4: 젠다이 | B4: ○ | C4: ○
A5: 욕조 | B5: ○ | C5: ○ | F5: 세면대 상부(1면) / 주방타일 인코너 / 주방창호(PL)주위
A6: 욕실문주위 | B6: ○ | C6: ○
A7: 샤워부스 | B7: ○ | C7: X | D7: 샤워부스공사 코킹포함
A8: EV홀천정코킹 | B8: X | C8: ○ | D8: 개정항목
A9: 현관디딤판+가구면 | B9: ○ | C9: ○
A10: 현관디딤판하부 | B10: ○ | C10: ○
A11: 현관굽도리하부 | B11: ○ | C11: ○
A12: 확장대상발코니(크랙유도줄눈) | B12: ○ | C12: X | D12: 항목삭제(현장 미시공항목)
A13: 조적+옹벽(발코니) | B13: ○ | C13: ○
A14: 주방타일 인코너 | B14: X | C14: ○ | D14: 미산출 부위
A15: 주방창호(PL)주위 | B15: X | C15: ○ | D15: 미산출 부위
A16: 현관방화문 주위 | B16: X | C16: ○ | D16: 미산출 부위

Sheet 하드웨어
A1: 구 분 | C1: 단 위 세 대 | J1: 공 용 부 | O1: 부 속 동 | Q1: 비고
C2: 강재창호 | E2: 목재/PL창호 | I2: AW/PW | J2: 강재창호 | N2: AW | O2: 강재 창호 | P2: 목재 창호
C3: 세대 현관 | D3: 대피 공간 | E3: 안방 | F3: 침실 | G3: 욕실 | H3: 주방 발코니 | I3: 배연창 | J3: 계단실 | K3: 지붕층 계단실 | L3: 양개 도어 | M3: SSD 도어 | N3: 배연창
A4: 도어록 | B4: 일반 | D4: ㅇ | J4: ㅇ | K4: ㅇ | L4: ㅇ | O4: ㅇ
B5: 공정 | L5: ㅇ
A6: 레버 핸들 | B6: 안방 | E6: ㅇ | Q6: 잠금장치 포함
B7: 침실 | F7: ㅇ | G7: ㅇ | P7: ㅇ
A8: 도어 체크 | B8: 일반 | C8: ㅇ | D8: o | L8: ㅇ | O8: ㅇ | Q8: 양개도어 2EA
B9: 자동폐쇄 | J9: ㅇ
B10: 파워형 | K10: ㅇ
A11: 도어 스톱 (개정) | B11: 침실 | E11: ㅇ | F11: ㅇ | P11: ㅇ | Q11: BUMP ON
B12: 일자형 | D12: ㅇ | G12: ㅇ | H12: ㅇ
A13: 정첩 | E13: ㅇ | F13: ㅇ | G13: ㅇ | P13: ㅇ | Q13: 3EA
A14: 손끼임방지 | E14: ㅇ | F14: ㅇ | G14: ㅇ | H14: △ (목재만) | P14: ㅇ
A15: 비상문자동개폐 | K15: ㅇ
A16: 우선순위조절기 | L16: ㅇ
A17: 플로어힌지 | M17: ㅇ
A18: 자동개폐장치 | I18: ㅇ | N18: ㅇ
A19: 오토힌지/ 마그네틱릴리즈 | J19: ㅇ | Q19: 상시개방 (매립형)

Sheet 부자재환산
A1: 구분 | B1: 품명 | C1: 규격 | D1: 단위 | E1: 소요량 | J1: 비고
E2: 시멘트 (TON) | F2: 시멘트 (포) | G2: 레미탈 (TON) | H2: 레미탈 (포) | I2: 모래
A3: 방수 | B3: 액체방수 | D3: M2 | F3: 0.336 | I3: 0.02
B4: 보호몰탈 | C4: 바닥,30T | D4: M2 | F4: 0.3413 | I4: 0.0273
C5: 벽,18T | D5: M2 | F5: 0.2048 | I5: 0.0164
B6: 방수몰탈 | C6: 20T | D6: M2 | F6: 0.22753 | I6: 0.0182
A7: 견출 | B7: 콘크리트면처리 | D7: M2 | H7: 0.03575 | V7: =75/1000 -> 0.075
A8: 조적 | B8: 시멘트벽돌쌓기 | C8: 0.5B | D8: M2 | H8: 0.9023
C9: 1.0B | D9: M2 | H9: 2.3663
B10: 시멘트벽돌세워쌓기 | C10: 0.5B | D10: M2 | H10: 0.5715
B11: 시멘트블럭보강쌓기 (1종사춤) | C11: 4"일면치장 | D11: M2 | H11: 0.3331
C12: 4"양면치장 | D12: M2 | H12: 0.3774
C13: 6"일면치장 | D13: M2 | H13: 0.4774
C14: 6"양면치장 | D14: M2 | H14: 0.5217
C15: 8"일면치장 | D15: M2 | H15: 0.5256
C16: 8"양면치장 | D16: M2 | H16: 0.5699
A17: 미장 | B17: 방바닥미장 | C17: 30T | D17: M2 | G17: 0.05775
C18: 40T | D18: M2 | G18: 0.077 | M18: =G18/40 -> 0.001925 | N18: =M18*60 -> 0.1155 | O18: =M18*120 -> 0.231 | P18: =M18*180 -> 0.3465 | Q18: =M18*195 -> 0.375375 | R18: =M18*135 -> 0.259875
B19: 시멘트몰탈 | C19: 바닥,30T | D19: M2 | H19: 1.4438
C20: 바닥,50T | D20: M2 | H20: 2.4063
C21: 바닥,120T | D21: M2 | H21: 5.7752
C22: 바닥,170T | D22: M2 | H22: 8.1815
C23: 벽초벌,9T | D23: M2 | H23: 0.4332
C24: 내벽,18T | D24: M2 | H24: 0.8663
C25: 외벽,24T | D25: M2 | H25: 1.155
B26: 계단마구리미장 | C26: W:150~300 | D26: M | H26: 0.5969
B27: 걸레받이몰탈 | C27: H:100 | D27: M | H27: 0.08663
B28: E/V주위사춤및미장 | C28: 몰탈사춤 | D28: M | H28: 0.2653
B29: 창틀,문틀주위사춤 | C29: 몰탈사춤 | D29: M | H29: 0.2653
B30: 경량기포콘크리트 | C30: 30T | D30: M3 | E30: 0.255
C31: 40T | D31: M3 | E31: 0.34
A32: 타일 | B32: 벽타일붙이기 | C32: 떠붙이기 | D32: M2 | H32: 0.7219
B33: 타일바탕몰탈 | C33: 내벽,15T | D33: M2 | H33: 0.7219 | N33: =0.165-0.03 -> 0.135
A34: 석 | B34: 지정석재(바닥) | C34: 몰탈20T | D34: M2 | F34: 0.2678 | I34: 0.0231
C35: 몰탈70T | D35: M2 | F35: 0.9371 | I35: 0.0809
B36: 지정석재(디딤판) | C36: W300/몰탈20T | D36: M | F36: 0.0803 | I36: 0.0069 | K36: =F34/20 -> 0.01339 | L36: =I34/20 -> 0.001155 | M36: 가로 | N36: 세로 | O36: 몰탈T | P36: 시멘트 | Q36: 모래
B37: 지정석재(챌판) | C37: 몰탈20T | D37: M2 | F37: 0.2678 | I37: 0.0231 | M37: 1.35 | N37: 0.14 | O37: 30 | P37: =ROUNDUP(($K$36*$O37)*($M37*$N37),4) -> 0.076 | Q37: =ROUND(($L$36*$O37)*($M37*$N37),4) -> 0.0065
M38: 1.4 | N38: 0.14 | O38: 30 | P38: =ROUNDUP(($K$36*$O38)*($M38*$N38),4) -> 0.0788 | Q38: =ROUND(($L$36*$O38)*($M38*$N38),4) -> 0.0068
M39: 1.6 | N39: 0.14 | O39: 30 | P39: =ROUNDUP(($K$36*$O39)*($M39*$N39),4) -> 0.09 | Q39: =ROUND(($L$36*$O39)*($M39*$N39),4) -> 0.0078
M40: 1.4 | N40: 0.14 | O40: 30 | P40: =ROUNDUP(($K$36*$O40)*($M40*$N40),4) -> 0.0788 | Q40: =ROUND(($L$36*$O40)*($M40*$N40),4) -> 0.0068
...

Sheet 재료할증
A1: 구 분 | D1: 단 위 | E1: 할증률 | F1: 비 고
A2: 레미콘 | B2: 버림 | D2: M3 | E2: 0.02
B3: 무근 | D3: M3 | E3: 0.02
B4: 철근 | D4: M3 | E4: 0.01
A5: 이형철근 | B5: 각종 | D5: TON | E5: 0.03
A6: 시멘트벽돌 | B6: 190*90*57 | D6: 매 | E6: 0.03 | F6: 치장(적)벽돌 포함
A7: 시멘트블록 | B7: 4" | D7: 매 | E7: 0.04
B8: 6" | D8: 매 | E8: 0.04
B9: 8" | D9: 매 | E9: 0.04
A10: 타 일 | B10: 세대 | C10: 벽 | D10: M2 | E10: 0 | F10: 타일나누기도 有 개정(최종 22.03.11_감사팀)
C11: 바닥 | D11: M2 | E11: 0
B12: 공용부 /부속동 | C12: 벽 | D12: M2 | E12: 0.05 | F12: 타일나누기도 無
C13: 바닥 | D13: M2 | E13: 0.03
C14: 계단 | D14: M2 | E14: 0.03
A15: 단열재 | B15: 각종 | D15: M2 | E15: 0.1

Sheet 주방가구
M8: A
J12: 하부장 | K12: 하부장
F15: B
K17: 아일랜드
L21: C
